Workbook

Sheet SEPTIEMBRE 2025
CN1: | | CP1: AG
Z2: Toma de VIH | AE2: SGB | AH2: VDRL | AJ2: Hepatitis B | AL2: Trabajo de Parto | AW2: PARTO | BC2: PUERPERIO | BL2: ANESTESIA Y/O ANALGESIA DEL PARTO | CB2: RESULTADO DEL RN | CH2: APEGO Y ACOMPAÑAMIENTO | CP2: INFORMACIÓN DE LOS PROFESIONALES | CU2: Ley N° 21.372 Dominga | CV2: Placenta | CX2: Registro Civil
A3: , | B3: Tipo de Paciente | C3: Origen Ingreso | D3: FECHA | E3: Hora | F3: PLAN DE PARTO (SI/NO) | G3: Visita Guiada | H3: Nombre completo | I3: RUN | J3: DV | K3: Inmigrante | L3: Nacionalidad | M3: Pueblo Originario | N3: Edad | O3: Discapacidad | P3: Privada de Libertad | Q3: Trans Masculino | R3: IMC | S3: Paridad | T3: Control Prenatal | U3: Consultorio de Origen | V3: Preeclampsia Severa | W3: Eclampsia | X3: Sepsis o Infección Sistemica Grave | Y3: Infección Ovular o Corioamnionitis | Z3: Otra Patología | AA3: Nº ARO | AB3: Se toma VIH en Prepartos | AC3: Se tomo VIH en Sala | AD3: 1°-2°-3° | AE3: Pesquisa | AF3: Resultado | AG3: Antibiotico por SGB (NO POR RPM) | AH3: Resultado VDRL durante embarazo | AI3: Tratamiento ATB por Sífilis al momento del Parto | AJ3: Examén Hepatitis B - Tomado | AK3: Derivación a Especialista (Gastro-Hepatologo) | AL3: Sem. Obst. (semanas) | AM3: Sem. Obst. (días) | AN3: Monitor | AO3: TTC | AP3: Inducción | AQ3: Aceleración ó Correción | AR3: N° TV | AS3: Rotura membrana | AT3: Tiempo membranas rotas | AU3: Tiempo dilatación | AV3: Tiempo Expulsivo | AW3: Libertad de Movimiento en Trabajo de Parto | AX3: Tipo de Régimen en Trabajo de Parto | AY3: Tipo de parto | AZ3: Alumbramiento Diriguido | BA3: Clasificación de Robson | BB3: Posición materna parto | BC3: Ofrecimiento de posiciones alternativas del Parto | BD3: Estado periné | BE3: Esteriliz. | BF3: Revision | BG3: Inercia Uterina | BH3: Restos Placentarios | BI3: Trauma | BJ3: Alteración de la Coagulación | BK3: Manejo Quirúrgico de Inercia Uterina | BL3: Histerectomía Obstétrica | BM3: Tranfusión Sanguínea | BN3: Anestesia Neuroaxial | BO3: Óxido nitroso | BP3: Analgesia endovenosa | BQ3: General | BR3: Local | BS3: Analgesia NO farmac. | BT3: Balón Kinesico | BU3: Lenteja de Parto | BV3: Rebozo | BW3: Aromaterapia | BX3: Anest. Peridural Solicitada por paciente | BY3: Anest. Peridural indicada por médico GO | BZ3: Anest. Peridural administrada | CA3: Tiempo de espera entre indicación médica y administración de Anest. Peridural | CB3: Sexo | CC3: Peso | CD3: Talla | CE3: Ligadura Tardia del Cordón (> a 1 minuto) | CF3: Apgar al minuto | CG3: Apgar a los 5 min | CH3: Tiempo de apego | CI3: Apego Canguro | CJ3: Acompañamiento Preparto | CK3: Acompañamiento Parto | CL3: Acomp. RN | CM3: Motivo parto NO acompañado | CN3: Persona acompañante | CO3: Acompañante secciona cordón | CP3: Profes. Responsable (Nombre - apellido) | CQ3: Alumno (Nombre - apellido) | CR3: Causa cesarea | CS3: OBSERVACIONES | CT3: USO DE SALA SAIP (SI/NO) | CU3: Cuales Recuerdos (De no entregar justificar motivo) | CV3: Retira Placenta | CW3: Estampado de Placenta | CX3: FOLIO VALIDO | CY3: FOLIO/S NULO/S | CZ3: Manejo del Dolor No Farmacologico
A4: 1 | B4: Institucional | C4: UEGO | D4: 45901 | E4: 0.41388889 | F4: NO | G4: NO | H4: NICOLE ANGELA FLORES ZAPATA | I4: 11111111 | J4: 0 | K4: NO | L4: CHILENA | M4: NO | N4: 27 | O4: NO | P4: NO | Q4: NO | R4: 35.8 | S4: 2 | T4: NO | U4: FEDERICO PUGA | V4: NO | W4: NO | X4: NO | Y4: NO | Z4: SI | AA4: 419 | AB4: NO | AC4: NO | AE4: SI | AF4: NEGATIVO | AG4: NO | AH4: NO REACTIVO | AI4: NO | AJ4: SI | AK4: NO | AL4: 38 | AM4: 2 | AN4: SI | AO4: NO | AP4: NO | AQ4: NO | AR4: 0 | AS4: IOP | AT4: IOP | AU4: NO | AV4: 0 | AW4: NO | AX4: CERO | AY4: EUTOCICO | AZ4: SI | BA4: Grupo 1 | BB4: SEMISENTADA | BC4: NO | BD4: INDEMNE | BE4: NO | BF4: SI | BG4: NO | BH4: NO | BI4: NO | BJ4: NO | BK4: NO | BL4: NO | BM4: NO | BN4: SI | BO4: NO | BP4: NO | BQ4: NO | BR4: NO | BS4: NO | BT4: NO | BU4: NO | BV4: NO | BW4: NO | BX4: NO | BY4: NO | BZ4: NO | CB4: MASCULINO | CC4: 3450 | CD4: 50 | CE4: NO | CF4: 8 | CG4: 9 | CH4: 4 | CI4: SI | CJ4: NO | CK4: SI | CL4: SI | CM4: NO DESEA | CN4: PAREJA | CO4: SI | CP4: DR RILKE GONZALEZ / DRA ULLOA | CR4: DOBLE CESAREA ANTERIOR | CT4: NO | CV4: NO | CW4: SI | CX4: 7787343
B5: Prehospitalario | C5: SALA | AF5: POSITIVO | AH5: REACTIVO | AS5: RAM | AW5: SI | AX5: LIQUIDO | AY5: DISTOCICO | BA5: Grupo 2.A | BB5: SENTADA | BC5: NO | BD5: DESGARRO G1 | BE5: NO | BF5: SI | BG5: NO | BH5: NO | BI5: NO | BJ5: NO | BK5: NO | BL5: NO | BM5: NO | BN5: SI | BO5: NO | BP5: NO | BQ5: NO | BR5: NO | BS5: NO | BT5: NO | BU5: NO | BV5: NO | BW5: NO | BX5: NO | BY5: NO | BZ5: NO | CB5: FEMENINO | CC5: 3350 | CD5: 50 | CE5: NO | CF5: 8 | CG5: 9 | CH5: 4 | CI5: SI | CJ5: NO | CL5: NO | CM5: NO LLEGA | CN5: MADRE | CO5: NO
B6: Fuera de la Red Asistencial | AS6: REM | AX6: COMÚN | AY6: CES. URGENCIA | BA6: Grupo 2.B | BB6: LITOTOMIA | BD6: DESGARRO G2 | CB6: INDETERMINADO | CM6: URGENCIA | CN6: HERMANA
B7: Domicilio con Atención Profesional | AS7: RPM | AX7: OTRO | AY7: CES.ELECTIVA | BA7: Grupo 3 | BB7: D. DORSAL | BD7: DESGARRO G3 A | CM7: NO TIENE ACOMPAÑANTE | CN7: AMIGA
B8: Domicilio sin Atención Profesional | BA8: Grupo 4 | BB8: CUADRÚPEDA | BD8: DESGARRO G3 B | CM8: RURALIDAD | CN8: OTRO
BA9: Grupo 5.1 | BB9: D. LATERAL | BD9: DESGARRO G3 C | CM9: SIN PASE DE MOVILIDAD | CN9: NADIE
BA10: Grupo 5.2 | BB10: DE PIE | BD10: DESGARRO G 4
BA11: Grupo 6 | BB11: CUCLILLAS | BD11: FISURA
BA12: Grupo 7 | BB12: OTRO | BD12: EPISIOTOMIA
BA13: Grupo 8
BA14: Grupo 9
BA15: Grupo 10
A164: 161
A165: 162
A166: 163
A167: 164
A168: 165
A169: 166
A170: 167
A171: 168
A172: 169
A173: 170
A174: 171
A175: 172
... A181: 178
BA1048576: 0 | BB1048576: D DORSAL | GL1048576: 0 | IA1048576: 0 | UC1048576: 0 | WK1048576: 0 | YJ1048576: 0 | ZJ1048576: 0 | ABH1048576: 0 | ACL1048576: 0 | ADF1048576: 0 | AGQ1048576: 0 | AHY1048576: 0 | ALM1048576: 0 | ALX1048576: 0

Sheet Hoja1

Sheet REM
B2: CARACTERISTICAS DEL PARTO | D2: TOTAL | E2: PARTOS SEGÚN EDAD DE LA MADRE | I2: PARTOS PREMATUROS (considerar sobre 22 semanas) | M2: Uso de oxitocina profiláctica | N2: Anestesia y/o Analgesia del parto (medidas farmacologicas y no farmacológica) | T2: Ligadura tardía del cordón (> 60 segundos) | U2: Contacto inmediato piel a piel >30 minutos | Y2: Lactancia materna en los primeros 60 minutos de vida (RN con peso de 2.500 grs. o más) | Z2: Alojamiento conjunto en puerperio inmediato | AA2: Atención con pertinencia cultural | AB2: Pueblos Originarios | AC2: Migrantes | AD2: Discapacidad | AE2: Privada de Libertad | AF2: Trans
E3: < 15 AÑOS | F3: 15 A 19 AÑOS | G3: 20 A 34 AÑOS | H3: ≥35 AÑOS | I3: Partos prematuros menos de 24 semanas | J3: Partos prematuros de 24 a 28 semanas | K3: Partos prematuros de 29 a 32 semanas | L3: Partos prematuros de 33 a 36 semanas | N3: Anestesia Neuroaxial | O3: Oxido nitroso | P3: Analgesia endovenosa | Q3: General | R3: Local | S3: Medidas no farmacológicas | U3: Con la Madre | W3: Con el padre o acompañante significativo
U4: RN peso menor o igual a 2.499 grs. | V4: RN con peso de 2.500 grs. o más | W4: RN peso menor o igual a 2.499 grs. | X4: RN con peso de 2.500 grs. o más | AF4: Masculino | AG4: Femenino
B5: TOTAL PARTOS | D5: =SUM(D6:D9) -> 1 | E5: =SUM(E6:E9) -> 0 | F5: =SUM(F6:F9) -> 0 | G5: =SUM(G6:G9) -> 1 | H5: =SUM(H6:H9) -> 0 | I5: =SUM(I6:I9) -> 0 | J5: =SUM(J6:J9) -> 0 | K5: =SUM(K6:K9) -> 0 | ... Y5: =SUM(Y6:Y9) -> 0 | AA5: =SUM(AA6:AA9) -> 0 | AB5: =SUM(AB6:AB9) -> 0 | AC5: =SUM(AC6:AC9) -> 0 | AD5: =SUM(AD6:AD9) -> 0 | AE5: =SUM(AE6:AE9) -> 0 | AF5: =SUM(AF6:AF9) -> 0 | AG5: =SUM(AG6:AG9) -> 0
B6: VAGINAL | D6: =SUM(E6:H6) -> 1 | E6: =COUNTIFS('SEPTIEMBRE 2025'!N:N, "<15",'SEPTIEMBRE 2025'!AY:AY, "EUTOCICO") -> 0 | F6: =COUNTIFS('SEPTIEMBRE 2025'!N:N, ">14",'SEPTIEMBRE 2025'!N:N, "<20", 'SEPTIEMBRE 2025'!AY:AY, "EUTOCICO") -> 0 | G6: =COUNTIFS('SEPTIEMBRE 2025'!N:N, ">19",'SEPTIEMBRE 2025'!N:N, "<35", 'SEPTIEMBRE 2025'!AY:AY, "EUTOCICO") -> 1 | H6: =COUNTIFS('SEPTIEMBRE 2025'!N:N, ">34", 'SEPTIEMBRE 2025'!AY:AY, "EUTOCICO") -> 0 | I6: =COUNTIFS('SEPTIEMBRE 2025'!AL:AL, "<24",'SEPTIEMBRE 2025'!AV:AV, "EUTOCICO") -> 0 | J6: =COUNTIFS('SEPTIEMBRE 2025'!AL:AL, ">23",'SEPTIEMBRE 2025'!AL:AL, "<29", 'SEPTIEMBRE 2025'!AY:AY, "EUTOCICO") -> 0 | K6: =COUNTIFS('SEPTIEMBRE 2025'!AL:AL, ">28",'SEPTIEMBRE 2025'!AL:AL, "<33", 'SEPTIEMBRE 2025'!AY:AY, "EUTOCICO") -> 0 | L6: =COUNTIFS('SEPTIEMBRE 2025'!AL:AL, ">32",'SEPTIEMBRE 2025'!AL:AL, "<37", 'SEPTIEMBRE 2025'!AY:AY, "EUTOCICO") -> 0 | M6: =COUNTIFS('SEPTIEMBRE 2025'!AZ:AZ, "SI", 'SEPTIEMBRE 2025'!AY:AY, "EUTOCICO") -> 1 | N6: =COUNTIFS('SEPTIEMBRE 2025'!BN:BN,"SI", 'SEPTIEMBRE 2025'!AY:AY, "EUTOCICO") -> 1 | O6: =COUNTIFS('SEPTIEMBRE 2025'!BO:BO, "SI", 'SEPTIEMBRE 2025'!AY:AY, "EUTOCICO") -> 0 | P6: =COUNTIFS('SEPTIEMBRE 2025'!BP:BP, "SI", 'SEPTIEMBRE 2025'!AY:AY, "EUTOCICO") -> 0 | Q6: =COUNTIFS('SEPTIEMBRE 2025'!BQ:BQ,"SI", 'SEPTIEMBRE 2025'!AY:AY, "EUTOCICO") -> 0 | R6: =COUNTIFS('SEPTIEMBRE 2025'!BR:BR,"SI", 'SEPTIEMBRE 2025'!AY:AY, "EUTOCICO") -> 0 | S6: =COUNTIFS('SEPTIEMBRE 2025'!BS:BS, "SI", 'SEPTIEMBRE 2025'!AY:AY, "EUTOCICO") -> 0 | T6: =COUNTIFS('SEPTIEMBRE 2025'!CE:CE, "SI", 'SEPTIEMBRE 2025'!AY:AY, "EUTOCICO") -> 0 | U6: =COUNTIFS('SEPTIEMBRE 2025'!CC:CC, "<2500",'SEPTIEMBRE 2025'!CH:CH, "4", 'SEPTIEMBRE 2025'!AY:AY, "EUTOCICO", 'SEPTIEMBRE 2025'!CI:CI, "NO") -> 0 | V6: =COUNTIFS('SEPTIEMBRE 2025'!AY:AY, "EUTOCICO",'SEPTIEMBRE 2025'!CC:CC, ">2499",'SEPTIEMBRE 2025'!CH:CH, "4", 'SEPTIEMBRE 2025'!CI:CI, "NO") -> 0 | W6: =COUNTIFS('SEPTIEMBRE 2025'!CC:CC, "<2500",'SEPTIEMBRE 2025'!CH:CH, "4", 'SEPTIEMBRE 2025'!AY:AY, "EUTOCICO", 'SEPTIEMBRE 2025'!CI:CI, "SI") -> 0 | X6: =COUNTIFS('SEPTIEMBRE 2025'!AY:AY, "EUTOCICO",'SEPTIEMBRE 2025'!CC:CC, ">2499",'SEPTIEMBRE 2025'!CH:CH, "4", 'SEPTIEMBRE 2025'!CI:CI, "SI") -> 1 | AA6: 0 | AB6: =COUNTIFS('SEPTIEMBRE 2025'!M:M, "SI",'SEPTIEMBRE 2025'!AY:AY, "EUTOCICO") -> 0 | AC6: =COUNTIFS('SEPTIEMBRE 2025'!K:K, "SI",'SEPTIEMBRE 2025'!AY:AY, "EUTOCICO") -> 0 | AD6: =COUNTIFS('SEPTIEMBRE 2025'!O:O, "SI",'SEPTIEMBRE 2025'!AY:AY, "EUTOCICO") -> 0 | AE6: =COUNTIFS('SEPTIEMBRE 2025'!P:P, "SI",'SEPTIEMBRE 2025'!AY:AY, "EUTOCICO") -> 0 | AF6: =COUNTIFS('SEPTIEMBRE 2025'!O:O, "SI",'SEPTIEMBRE 2025'!AY:AY, "EUTOCICO") -> 0 | AG6: 0
B7: INSTRUMENTAL | D7: =SUM(E7:H7) -> 0 | E7: =COUNTIFS('SEPTIEMBRE 2025'!N:N, "<15", 'SEPTIEMBRE 2025'!AY:AY, "DISTOCICO") -> 0 | F7: =COUNTIFS('SEPTIEMBRE 2025'!N:N, ">14",'SEPTIEMBRE 2025'!N:N, "<20", 'SEPTIEMBRE 2025'!AY:AY, "DISTOCICO") -> 0 | G7: =COUNTIFS('SEPTIEMBRE 2025'!N:N, ">19",'SEPTIEMBRE 2025'!N:N, "<35", 'SEPTIEMBRE 2025'!AY:AY, "DISTOCICO") -> 0 | H7: =COUNTIFS('SEPTIEMBRE 2025'!N:N, ">34", 'SEPTIEMBRE 2025'!AY:AY, "DISTOCICO") -> 0 | I7: =COUNTIFS('SEPTIEMBRE 2025'!AL:AL, "<24",'SEPTIEMBRE 2025'!AY:AY, "DISTOCICO") -> 0 | J7: =COUNTIFS('SEPTIEMBRE 2025'!AL:AL, ">23",'SEPTIEMBRE 2025'!AL:AL, "<29", 'SEPTIEMBRE 2025'!AY:AY, "DISTOCICO") -> 0 | K7: =COUNTIFS('SEPTIEMBRE 2025'!AL:AL, ">28",'SEPTIEMBRE 2025'!AL:AL, "<33", 'SEPTIEMBRE 2025'!AY:AY, "DISTOCICO") -> 0 | L7: =COUNTIFS('SEPTIEMBRE 2025'!AL:AL, ">32",'SEPTIEMBRE 2025'!AL:AL, "<37", 'SEPTIEMBRE 2025'!AY:AY, "DISTOCICO") -> 0 | M7: =COUNTIFS('SEPTIEMBRE 2025'!AZ:AZ, "SI", 'SEPTIEMBRE 2025'!AY:AY, "DISTOCICO") -> 0 | N7: =COUNTIFS('SEPTIEMBRE 2025'!BN:BN,"SI", 'SEPTIEMBRE 2025'!AY:AY, "DISTOCICO") -> 1 | O7: =COUNTIFS('SEPTIEMBRE 2025'!BO:BO, "SI", 'SEPTIEMBRE 2025'!AY:AY, "DISTOCICO") -> 0 | P7: =COUNTIFS('SEPTIEMBRE 2025'!BP:BP, "SI", 'SEPTIEMBRE 2025'!AY:AY, "DISTOCICO") -> 0 | Q7: =COUNTIFS('SEPTIEMBRE 2025'!BQ:BQ,"SI", 'SEPTIEMBRE 2025'!AY:AY, "DISTOCICO") -> 0 | R7: =COUNTIFS('SEPTIEMBRE 2025'!BR:BR,"SI", 'SEPTIEMBRE 2025'!AY:AY, "DISTOCICO") -> 0 | S7: =COUNTIFS('SEPTIEMBRE 2025'!BS:BS, "SI", 'SEPTIEMBRE 2025'!AY:AY, "DISTOCICO") -> 0 | T7: =COUNTIFS('SEPTIEMBRE 2025'!CE:CE, "SI", 'SEPTIEMBRE 2025'!AY:AY, "DISTOCICO") -> 0 | U7: =COUNTIFS('SEPTIEMBRE 2025'!CC:CC, "<2500",'SEPTIEMBRE 2025'!CH:CH, "4", 'SEPTIEMBRE 2025'!AY:AY, "DISTOCICO", 'SEPTIEMBRE 2025'!CI:CI, "NO") -> 0 | V7: =COUNTIFS('SEPTIEMBRE 2025'!AY:AY, "DISTOCICO",'SEPTIEMBRE 2025'!CC:CC, ">2499",'SEPTIEMBRE 2025'!CH:CH, "4", 'SEPTIEMBRE 2025'!CI:CI, "NO") -> 0 | W7: =COUNTIFS('SEPTIEMBRE 2025'!CC:CC, "<2500",'SEPTIEMBRE 2025'!CH:CH, "4", 'SEPTIEMBRE 2025'!AY:AY, "DISTOCICO", 'SEPTIEMBRE 2025'!CI:CI, "SI") -> 0 | X7: =COUNTIFS('SEPTIEMBRE 2025'!AY:AY, "DISTOCICO",'SEPTIEMBRE 2025'!CC:CC, ">2499",'SEPTIEMBRE 2025'!CH:CH, "4", 'SEPTIEMBRE 2025'!CI:CI, "SI") -> 1 | AA7: 0 | AB7: =COUNTIFS('SEPTIEMBRE 2025'!M:M, "SI",'SEPTIEMBRE 2025'!AY:AY, "DISTOCICO") -> 0 | AC7: =COUNTIFS('SEPTIEMBRE 2025'!K:K, "SI",'SEPTIEMBRE 2025'!AY:AY, "DISTOCICO") -> 0 | AD7: =COUNTIFS('SEPTIEMBRE 2025'!O:O, "SI",'SEPTIEMBRE 2025'!AY:AY, "DISTOCICO") -> 0 | AE7: =COUNTIFS('SEPTIEMBRE 2025'!P:P, "SI",'SEPTIEMBRE 2025'!AY:AY, "DISTOCICO") -> 0 | AF7: =COUNTIFS('SEPTIEMBRE 2025'!O:O, "SI",'SEPTIEMBRE 2025'!AY:AY, "DISTOCICO") -> 0 | AG7: 0
B8: CESÁREA ELECTIVA | D8: =SUM(E8:H8) -> 0 | E8: =COUNTIFS('SEPTIEMBRE 2025'!N:N, "<15", 'SEPTIEMBRE 2025'!AY:AY, "CES,ELECTIVA") -> 0 | F8: =COUNTIFS('SEPTIEMBRE 2025'!N:N, ">14",'SEPTIEMBRE 2025'!N:N, "<20", 'SEPTIEMBRE 2025'!AY:AY, "CES.ELECTIVA") -> 0 | G8: =COUNTIFS('SEPTIEMBRE 2025'!N:N, ">19",'SEPTIEMBRE 2025'!N:N, "<35", 'SEPTIEMBRE 2025'!AY:AY, "CES.ELECTIVA") -> 0 | H8: =COUNTIFS('SEPTIEMBRE 2025'!N:N, ">34", 'SEPTIEMBRE 2025'!AY:AY,"CES.ELECTIVA") -> 0 | I8: =COUNTIFS('SEPTIEMBRE 2025'!AL:AL, "<24",'SEPTIEMBRE 2025'!AY:AY, "CES.ELECTIVA") -> 0 | J8: =COUNTIFS('SEPTIEMBRE 2025'!AL:AL, ">23", 'SEPTIEMBRE 2025'!AL:AL, "<29",'SEPTIEMBRE 2025'!AY:AY, "CES.ELECTIVA") -> 0 | K8: =COUNTIFS('SEPTIEMBRE 2025'!AL:AL, ">28",'SEPTIEMBRE 2025'!AL:AL, "<33", 'SEPTIEMBRE 2025'!AY:AY, "CES.ELECTIVA") -> 0 | L8: =COUNTIFS('SEPTIEMBRE 2025'!AL:AL, ">32",'SEPTIEMBRE 2025'!AL:AL, "<37", 'SEPTIEMBRE 2025'!AY:AY, "CES.ELECTIVA") -> 0 | M8: =COUNTIFS('SEPTIEMBRE 2025'!AZ:AZ, "SI", 'SEPTIEMBRE 2025'!AY:AY, "CES.ELECTIVA") -> 0 | N8: =COUNTIFS('SEPTIEMBRE 2025'!BN:BN,"SI", 'SEPTIEMBRE 2025'!AY:AY, "CES.ELECTIVA") -> 0 | O8: =COUNTIFS('SEPTIEMBRE 2025'!BO:BO, "SI", 'SEPTIEMBRE 2025'!AY:AY, "CES.ELECTIVA") -> 0 | P8: =COUNTIFS('SEPTIEMBRE 2025'!BP:BP, "SI", 'SEPTIEMBRE 2025'!AY:AY, "CES.ELECTIVA") -> 0 | Q8: =COUNTIFS('SEPTIEMBRE 2025'!BQ:BQ,"SI", 'SEPTIEMBRE 2025'!AY:AY, "CES.ELECTIVA") -> 0 | R8: =COUNTIFS('SEPTIEMBRE 2025'!BR:BR,"SI", 'SEPTIEMBRE 2025'!AY:AY, "CES.ELECTIVA") -> 0 | S8: =COUNTIFS('SEPTIEMBRE 2025'!BS:BS, "SI", 'SEPTIEMBRE 2025'!AY:AY, "CES.ELECTIVA") -> 0 | T8: =COUNTIFS('SEPTIEMBRE 2025'!CE:CE, "SI", 'SEPTIEMBRE 2025'!AY:AY, "CES.ELECTIVA") -> 0 | U8: =COUNTIFS('SEPTIEMBRE 2025'!CC:CC, "<2500",'SEPTIEMBRE 2025'!CH:CH, "4", 'SEPTIEMBRE 2025'!AY:AY, "CES.ELETIVA", 'SEPTIEMBRE 2025'!CI:CI, "NO") -> 0 | V8: =COUNTIFS('SEPTIEMBRE 2025'!AY:AY, "CES.ELECTIVA",'SEPTIEMBRE 2025'!CC:CC, ">2499",'SEPTIEMBRE 2025'!CH:CH, "4", 'SEPTIEMBRE 2025'!CI:CI, "NO") -> 0 | W8: =COUNTIFS('SEPTIEMBRE 2025'!CC:CC, "<2500",'SEPTIEMBRE 2025'!CH:CH, "4", 'SEPTIEMBRE 2025'!AY:AY, "CES.ELETIVA", 'SEPTIEMBRE 2025'!CI:CI, "SI") -> 0 | X8: =COUNTIFS('SEPTIEMBRE 2025'!AY:AY, "CES.ELECTIVA",'SEPTIEMBRE 2025'!CC:CC, ">2499",'SEPTIEMBRE 2025'!CH:CH, "4", 'SEPTIEMBRE 2025'!CI:CI, "SI") -> 0 | AA8: 0 | AB8: =COUNTIFS('SEPTIEMBRE 2025'!M:M, "SI",'SEPTIEMBRE 2025'!AY:AY, "CES.ELECTIVA") -> 0 | AC8: =COUNTIFS('SEPTIEMBRE 2025'!K:K, "<15", 'SEPTIEMBRE 2025'!AY:AY, "CES.ELECTIVA") -> 0 | AD8: =COUNTIFS('SEPTIEMBRE 2025'!O:O, "SI",'SEPTIEMBRE 2025'!AY:AY, "CES.ELECTIVA") -> 0 | AE8: =COUNTIFS('SEPTIEMBRE 2025'!P:P, "SI",'SEPTIEMBRE 2025'!AY:AY, "CES.ELECTIVA") -> 0 | AF8: =COUNTIFS('SEPTIEMBRE 2025'!K:K, "<15", 'SEPTIEMBRE 2025'!AY:AY, "CES.ELECTIVA") -> 0 | AG8: 0
B9: CESÁREA URGENCIA | D9: =SUM(E9:H9) -> 0 | E9: =COUNTIFS('SEPTIEMBRE 2025'!N:N, "<15", 'SEPTIEMBRE 2025'!AY:AY, "CES. URGENCIA") -> 0 | F9: =COUNTIFS('SEPTIEMBRE 2025'!N:N, ">14",'SEPTIEMBRE 2025'!N:N, "<20", 'SEPTIEMBRE 2025'!AY:AY, "CES. URGENCIA") -> 0 | G9: =COUNTIFS('SEPTIEMBRE 2025'!N:N, ">19",'SEPTIEMBRE 2025'!N:N, "<35", 'SEPTIEMBRE 2025'!AY:AY, "CES. URGENCIA") -> 0 | H9: =COUNTIFS('SEPTIEMBRE 2025'!N:N, ">34", 'SEPTIEMBRE 2025'!AY:AY,"CES. URGENCIA") -> 0 | I9: =COUNTIFS('SEPTIEMBRE 2025'!AL:AL, "<24",'SEPTIEMBRE 2025'!AY:AY, "CES. URGENCIA") -> 0 | J9: =COUNTIFS('SEPTIEMBRE 2025'!AL:AL, ">23",'SEPTIEMBRE 2025'!AL:AL, "<29", 'SEPTIEMBRE 2025'!AY:AY, "CES. URGENCIA") -> 0 | K9: =COUNTIFS('SEPTIEMBRE 2025'!AL:AL, ">28",'SEPTIEMBRE 2025'!AL:AL, "<33",'SEPTIEMBRE 2025'!AY:AY, "CES. URGENCIA") -> 0 | L9: =COUNTIFS('SEPTIEMBRE 2025'!AL:AL, ">32",'SEPTIEMBRE 2025'!AL:AL, "<37", 'SEPTIEMBRE 2025'!AY:AY, "CES. URGENCIA") -> 0 | M9: =COUNTIFS('SEPTIEMBRE 2025'!AZ:AZ, "SI", 'SEPTIEMBRE 2025'!AY:AY, "CES. URGENCIA") -> 0 | N9: =COUNTIFS('SEPTIEMBRE 2025'!BN:BN,"SI", 'SEPTIEMBRE 2025'!AY:AY, "CES. URGENCIA") -> 0 | O9: =COUNTIFS('SEPTIEMBRE 2025'!BO:BO, "SI", 'SEPTIEMBRE 2025'!AY:AY, "CES. URGENCIA") -> 0 | P9: =COUNTIFS('SEPTIEMBRE 2025'!BP:BP, "SI", 'SEPTIEMBRE 2025'!AY:AY, "CES. URGENCIA") -> 0 | Q9: =COUNTIFS('SEPTIEMBRE 2025'!BQ:BQ,"SI", 'SEPTIEMBRE 2025'!AY:AY, "CES. URGENCIA") -> 0 | R9: =COUNTIFS('SEPTIEMBRE 2025'!BR:BR,"SI", 'SEPTIEMBRE 2025'!AY:AY, "CES. URGENCIA") -> 0 | S9: =COUNTIFS('SEPTIEMBRE 2025'!BS:BS, "SI", 'SEPTIEMBRE 2025'!AY:AY, "CES. URGENCIA") -> 0 | T9: =COUNTIFS('SEPTIEMBRE 2025'!CE:CE, "SI", 'SEPTIEMBRE 2025'!AY:AY, "CES. URGENCIA") -> 0 | U9: =COUNTIFS('SEPTIEMBRE 2025'!CC:CC, "<2500",'SEPTIEMBRE 2025'!CH:CH, "4", 'SEPTIEMBRE 2025'!AY:AY, "CES. URGENCIA", 'SEPTIEMBRE 2025'!CI:CI, "NO") -> 0 | V9: =COUNTIFS('SEPTIEMBRE 2025'!AY:AY, "CES. URGENCIA",'SEPTIEMBRE 2025'!CC:CC, ">2499",'SEPTIEMBRE 2025'!CH:CH, "4", 'SEPTIEMBRE 2025'!CI:CI, "NO") -> 0 | W9: =COUNTIFS('SEPTIEMBRE 2025'!CC:CC, "<2500",'SEPTIEMBRE 2025'!CH:CH, "4", 'SEPTIEMBRE 2025'!AY:AY, "CES. URGENCIA", 'SEPTIEMBRE 2025'!CI:CI, "SI") -> 0 | X9: =COUNTIFS('SEPTIEMBRE 2025'!AY:AY, "CES. URGENCIA",'SEPTIEMBRE 2025'!CC:CC, ">2499",'SEPTIEMBRE 2025'!CH:CH, "4", 'SEPTIEMBRE 2025'!CI:CI, "SI") -> 0 | AA9: 0 | AB9: =COUNTIFS('SEPTIEMBRE 2025'!M:M, "SI",'SEPTIEMBRE 2025'!AY:AY, "CES. URGENCIA") -> 0 | AC9: =COUNTIFS('SEPTIEMBRE 2025'!K:K, "<15", 'SEPTIEMBRE 2025'!AY:AY, "CES. URGENCIA") -> 0 | AD9: =COUNTIFS('SEPTIEMBRE 2025'!O:O, "SI",'SEPTIEMBRE 2025'!AY:AY, "CES. URGENCIA") -> 0 | AE9: =COUNTIFS('SEPTIEMBRE 2025'!P:P, "SI",'SEPTIEMBRE 2025'!AY:AY, "CES. URGENCIA") -> 0 | AF9: =COUNTIFS('SEPTIEMBRE 2025'!K:K, "<15", 'SEPTIEMBRE 2025'!AY:AY, "CES. URGENCIA") -> 0 | AG9: 0
B10: PARTO PREHOSPITALARIO (en establecimientos salud o ambulancias) | D10: =SUM(E10:H10) -> 0 | E10: =COUNTIFS('SEPTIEMBRE 2025'!N:N, "<15",'SEPTIEMBRE 2025'!AY:AY, "EUTOCICO", 'SEPTIEMBRE 2025'!B:B, "PREHOSPITALARIO") -> 0 | F10: =COUNTIFS('SEPTIEMBRE 2025'!N:N, ">14",'SEPTIEMBRE 2025'!N:N, "<20", 'SEPTIEMBRE 2025'!AY:AY, "EUTOCICO", 'SEPTIEMBRE 2025'!B:B, "PREHOSPITALARIO") -> 0 | G10: =COUNTIFS('SEPTIEMBRE 2025'!O:O, ">14",'SEPTIEMBRE 2025'!O:O, "<20", 'SEPTIEMBRE 2025'!AZ:AZ, "EUTOCICO", 'SEPTIEMBRE 2025'!C:C, "PREHOSPITALARIO") -> 0 | H10: =COUNTIFS('SEPTIEMBRE 2025'!P:P, ">14",'SEPTIEMBRE 2025'!P:P, "<20", 'SEPTIEMBRE 2025'!BA:BA, "EUTOCICO", 'SEPTIEMBRE 2025'!D:D, "PREHOSPITALARIO") -> 0 | I10: =COUNTIFS('SEPTIEMBRE 2025'!Q:Q, ">14",'SEPTIEMBRE 2025'!Q:Q, "<20", 'SEPTIEMBRE 2025'!BB:BB, "EUTOCICO", 'SEPTIEMBRE 2025'!E:E, "PREHOSPITALARIO") -> 0 | J10: =COUNTIFS('SEPTIEMBRE 2025'!R:R, ">14",'SEPTIEMBRE 2025'!R:R, "<20", 'SEPTIEMBRE 2025'!BC:BC, "EUTOCICO", 'SEPTIEMBRE 2025'!G:G, "PREHOSPITALARIO") -> 0 | K10: =COUNTIFS('SEPTIEMBRE 2025'!S:S, ">14",'SEPTIEMBRE 2025'!S:S, "<20", 'SEPTIEMBRE 2025'!BD:BD, "EUTOCICO", 'SEPTIEMBRE 2025'!H:H, "PREHOSPITALARIO") -> 0 | L10: =COUNTIFS('SEPTIEMBRE 2025'!T:T, ">14",'SEPTIEMBRE 2025'!T:T, "<20", 'SEPTIEMBRE 2025'!BE:BE, "EUTOCICO", 'SEPTIEMBRE 2025'!I:I, "PREHOSPITALARIO") -> 0 | M10: =COUNTIFS('SEPTIEMBRE 2025'!U:U, ">14",'SEPTIEMBRE 2025'!U:U, "<20", 'SEPTIEMBRE 2025'!BF:BF, "EUTOCICO", 'SEPTIEMBRE 2025'!J:J, "PREHOSPITALARIO") -> 0 | N10: =COUNTIFS('SEPTIEMBRE 2025'!V:V, ">14",'SEPTIEMBRE 2025'!V:V, "<20", 'SEPTIEMBRE 2025'!BG:BG, "EUTOCICO", 'SEPTIEMBRE 2025'!K:K, "PREHOSPITALARIO") -> 0 | O10: =COUNTIFS('SEPTIEMBRE 2025'!W:W, ">14",'SEPTIEMBRE 2025'!W:W, "<20", 'SEPTIEMBRE 2025'!BH:BH, "EUTOCICO", 'SEPTIEMBRE 2025'!L:L, "PREHOSPITALARIO") -> 0 | P10: =COUNTIFS('SEPTIEMBRE 2025'!X:X, ">14",'SEPTIEMBRE 2025'!X:X, "<20", 'SEPTIEMBRE 2025'!BI:BI, "EUTOCICO", 'SEPTIEMBRE 2025'!M:M, "PREHOSPITALARIO") -> 0 | Q10: =COUNTIFS('SEPTIEMBRE 2025'!Y:Y, ">14",'SEPTIEMBRE 2025'!Y:Y, "<20", 'SEPTIEMBRE 2025'!BJ:BJ, "EUTOCICO", 'SEPTIEMBRE 2025'!N:N, "PREHOSPITALARIO") -> 0 | R10: =COUNTIFS('SEPTIEMBRE 2025'!Z:Z, ">14",'SEPTIEMBRE 2025'!Z:Z, "<20", 'SEPTIEMBRE 2025'!BK:BK, "EUTOCICO", 'SEPTIEMBRE 2025'!O:O, "PREHOSPITALARIO") -> 0 | S10: =COUNTIFS('SEPTIEMBRE 2025'!AA:AA, ">14",'SEPTIEMBRE 2025'!AA:AA, "<20", 'SEPTIEMBRE 2025'!BL:BL, "EUTOCICO", 'SEPTIEMBRE 2025'!P:P, "PREHOSPITALARIO") -> 0 | T10: =COUNTIFS('SEPTIEMBRE 2025'!AB:AB, ">14",'SEPTIEMBRE 2025'!AB:AB, "<20", 'SEPTIEMBRE 2025'!BM:BM, "EUTOCICO", 'SEPTIEMBRE 2025'!Q:Q, "PREHOSPITALARIO") -> 0 | U10: =COUNTIFS('SEPTIEMBRE 2025'!AC:AC, ">14",'SEPTIEMBRE 2025'!AC:AC, "<20", 'SEPTIEMBRE 2025'!BN:BN, "EUTOCICO", 'SEPTIEMBRE 2025'!R:R, "PREHOSPITALARIO") -> 0 | V10: =COUNTIFS('SEPTIEMBRE 2025'!AD:AD, ">14",'SEPTIEMBRE 2025'!AD:AD, "<20", 'SEPTIEMBRE 2025'!BO:BO, "EUTOCICO", 'SEPTIEMBRE 2025'!S:S, "PREHOSPITALARIO") -> 0 | W10: =COUNTIFS('SEPTIEMBRE 2025'!AE:AE, ">14",'SEPTIEMBRE 2025'!AE:AE, "<20", 'SEPTIEMBRE 2025'!BP:BP, "EUTOCICO", 'SEPTIEMBRE 2025'!T:T, "PREHOSPITALARIO") -> 0 | X10: =COUNTIFS('SEPTIEMBRE 2025'!AF:AF, ">14",'SEPTIEMBRE 2025'!AF:AF, "<20", 'SEPTIEMBRE 2025'!BQ:BQ, "EUTOCICO", 'SEPTIEMBRE 2025'!U:U, "PREHOSPITALARIO") -> 0 | Y10: =COUNTIFS('SEPTIEMBRE 2025'!AG:AG, ">14",'SEPTIEMBRE 2025'!AG:AG, "<20", 'SEPTIEMBRE 2025'!BR:BR, "EUTOCICO", 'SEPTIEMBRE 2025'!V:V, "PREHOSPITALARIO") -> 0 | Z10: =COUNTIFS('SEPTIEMBRE 2025'!AH:AH, ">14",'SEPTIEMBRE 2025'!AH:AH, "<20", 'SEPTIEMBRE 2025'!BS:BS, "EUTOCICO", 'SEPTIEMBRE 2025'!W:W, "PREHOSPITALARIO") -> 0 | AA10: =COUNTIFS('SEPTIEMBRE 2025'!AI:AI, ">14",'SEPTIEMBRE 2025'!AI:AI, "<20", 'SEPTIEMBRE 2025'!BT:BT, "EUTOCICO", 'SEPTIEMBRE 2025'!X:X, "PREHOSPITALARIO") -> 0 | AB10: =COUNTIFS('SEPTIEMBRE 2025'!AJ:AJ, ">14",'SEPTIEMBRE 2025'!AJ:AJ, "<20", 'SEPTIEMBRE 2025'!BU:BU, "EUTOCICO", 'SEPTIEMBRE 2025'!Y:Y, "PREHOSPITALARIO") -> 0 | AC10: =COUNTIFS('SEPTIEMBRE 2025'!AK:AK, ">14",'SEPTIEMBRE 2025'!AK:AK, "<20", 'SEPTIEMBRE 2025'!BV:BV, "EUTOCICO", 'SEPTIEMBRE 2025'!Z:Z, "PREHOSPITALARIO") -> 0 | AD10: =COUNTIFS('SEPTIEMBRE 2025'!AL:AL, ">14",'SEPTIEMBRE 2025'!AL:AL, "<20", 'SEPTIEMBRE 2025'!BW:BW, "EUTOCICO", 'SEPTIEMBRE 2025'!AA:AA, "PREHOSPITALARIO") -> 0 | AE10: =COUNTIFS('SEPTIEMBRE 2025'!AP:AP, ">14",'SEPTIEMBRE 2025'!AP:AP, "<20", 'SEPTIEMBRE 2025'!BX:BX, "EUTOCICO", 'SEPTIEMBRE 2025'!AB:AB, "PREHOSPITALARIO") -> 0 | AF10: =COUNTIFS('SEPTIEMBRE 2025'!AN:AN, ">14",'SEPTIEMBRE 2025'!AN:AN, "<20", 'SEPTIEMBRE 2025'!BY:BY, "EUTOCICO", 'SEPTIEMBRE 2025'!AC:AC, "PREHOSPITALARIO") -> 0 | AG10: =COUNTIFS('SEPTIEMBRE 2025'!AP:AP, ">14",'SEPTIEMBRE 2025'!AP:AP, "<20", 'SEPTIEMBRE 2025'!BZ:BZ, "EUTOCICO", 'SEPTIEMBRE 2025'!AD:AD, "PREHOSPITALARIO") -> 0
B11: Plan de parto | D11: 0 | E11: 0 | F11: 0 | G11: 0 | H11: 0 | I11: 0 | J11: 0 | K11: 0 | L11: 0 | M11: 0 | N11: 0 | O11: 0 | P11: 0 | Q11: 0 | R11: 0 | S11: 0 | T11: 0 | U11: 0 | V11: 0 | W11: 0 | X11: 0 | Y11: 0 | Z11: 0 | AA11: 0 | AB11: 0 | AC11: 0 | AD11: 0 | AE11: 0 | AF11: 0 | AG11: 0
B12: PARTOS FUERA DE LA RED DE SALUD | D12: 0 | E12: 0 | F12: 0 | G12: 0 | H12: 0 | I12: 0 | J12: 0 | K12: 0 | L12: 0 | M12: 0 | N12: 0 | O12: 0 | P12: 0 | Q12: 0 | R12: 0 | S12: 0 | T12: 0 | U12: 0 | V12: 0 | W12: 0 | X12: 0 | Y12: 0 | Z12: 0 | AA12: 0 | AB12: 0 | AC12: 0 | AD12: 0 | AE12: 0 | AF12: 0 | AG12: 0
B13: ENTREGA DE PLACENTA A SOLICITUD | D13: 0 | E13: 0 | F13: 0 | G13: 0 | H13: 0 | I13: 0 | J13: 0 | K13: 0 | L13: 0 | M13: 0 | N13: 0 | O13: 0 | P13: 0 | Q13: 0 | R13: 0 | S13: 0 | T13: 0 | U13: 0 | V13: 0 | W13: 0 | X13: 0 | Y13: 0 | Z13: 0 | AA13: 0 | AB13: 0 | AC13: 0 | AD13: 0 | AE13: 0 | AF13: 0 | AG13: 0
B14: EMBARAZO NO CONTROLADO | D14: 0 | E14: 0 | F14: 0 | G14: 0 | H14: 0 | I14: 0 | J14: 0 | K14: 0 | L14: 0 | M14: 0 | N14: 0 | O14: 0 | P14: 0 | Q14: 0 | R14: 0 | S14: 0 | T14: 0 | U14: 0 | V14: 0 | W14: 0 | X14: 0 | Y14: 0 | Z14: 0 | AA14: 0 | AB14: 0 | AC14: 0 | AD14: 0 | AE14: 0 | AF14: 0 | AG14: 0
B15: PARTO EN DOMICILIO | C15: CON ATENCIÓN PROFESIONAL | D15: 0 | E15: 0 | F15: 0 | G15: 0 | H15: 0 | I15: 0 | J15: 0 | K15: 0 | L15: 0 | M15: 0 | N15: 0 | O15: 0 | P15: 0 | Q15: 0 | R15: 0 | S15: 0 | T15: 0 | U15: 0 | V15: 0 | W15: 0 | X15: 0 | Y15: 0 | Z15: 0 | AA15: 0 | AB15: 0 | AC15: 0 | AD15: 0 | AE15: 0 | AF15: 0 | AG15: 0
C16: SIN ATENCIÓN PROFESIONAL | D16: 0 | E16: 0 | F16: 0 | G16: 0 | H16: 0 | I16: 0 | J16: 0 | K16: 0 | L16: 0 | M16: 0 | N16: 0 | O16: 0 | P16: 0 | Q16: 0 | R16: 0 | S16: 0 | T16: 0 | U16: 0 | V16: 0 | W16: 0 | X16: 0 | Y16: 0 | Z16: 0 | AA16: 0 | AB16: 0 | AC16: 0 | AD16: 0 | AE16: 0 | AF16: 0 | AG16: 0
I19: EUTOCICO | L19: DISTOCICO
B20: CARACTERISTICAS DEL MODELO DE ATENCION | D20: TOTAL | E20: <28 semanas | F20: 28 a 37 semanas | G20: 38 semanas y más | I20: <28 semanas | J20: 28 a 37 semanas | K20: 38 semanas y más | L20: <28 semanas | M20: 29 a 37 semanas | N20: 39 semanas y más
B21: ESPONTANEO | D21: =SUM(E21:G21) -> 1 | E21: =I21+L21 -> 0 | F21: =J21+M21 -> 0 | G21: =K21+N21 -> 1 | I21: =COUNTIFS('SEPTIEMBRE 2025'!AL:AL, "<28",'SEPTIEMBRE 2025'!AY:AY, "EUTOCICO", 'SEPTIEMBRE 2025'!AP:AP,"NO") -> 0 | J21: =COUNTIFS('SEPTIEMBRE 2025'!AL:AL, "<38", 'SEPTIEMBRE 2025'!AL:AL, ">27",'SEPTIEMBRE 2025'!AY:AY, "EUTOCICO",'SEPTIEMBRE 2025'!AP:AP,"NO") -> 0 | K21: =COUNTIFS('SEPTIEMBRE 2025'!AL:AL, ">37",'SEPTIEMBRE 2025'!AY:AY, "EUTOCICO", 'SEPTIEMBRE 2025'!AP:AP,"NO") -> 1 | L21: =COUNTIFS('SEPTIEMBRE 2025'!AL:AL, "<28",'SEPTIEMBRE 2025'!AY:AY, "DISTOCICO",'SEPTIEMBRE 2025'!AP:AP,"NO") -> 0 | M21: =COUNTIFS('SEPTIEMBRE 2025'!AL:AL, "<38", 'SEPTIEMBRE 2025'!AL:AL, ">27",'SEPTIEMBRE 2025'!AY:AY, "DISTOCICO",'SEPTIEMBRE 2025'!AP:AP,"NO") -> 0 | N21: =COUNTIFS('SEPTIEMBRE 2025'!AL:AL, ">37",'SEPTIEMBRE 2025'!AY:AY, "DISTOCICO", 'SEPTIEMBRE 2025'!AP:AP,"NO") -> 0
B22: INDUCIDOS | C22: MECÁNICA | D22: =SUM(E22:G22) -> 0 | E22: 0 | F22: 0 | G22: 0 | I22: 0 | J22: 0 | K22: 0 | L22: 0 | M22: 0 | N22: 0
C23: FARMACOLÓGICA | D23: =SUM(E23:G23) -> 0 | E23: =I23+L23 -> 0 | F23: =J23+M23 -> 0 | G23: =K23+N23 -> 0 | I23: =COUNTIFS('SEPTIEMBRE 2025'!AL:AL, "<28",'SEPTIEMBRE 2025'!AY:AY, "EUTOCICO",'SEPTIEMBRE 2025'!AP:AP,"SI") -> 0 | J23: =COUNTIFS('SEPTIEMBRE 2025'!AL:AL, "<38", 'SEPTIEMBRE 2025'!AL:AL, ">27",'SEPTIEMBRE 2025'!AY:AY, "EUTOCICO", 'SEPTIEMBRE 2025'!AP:AP,"SI") -> 0 | K23: =COUNTIFS('SEPTIEMBRE 2025'!AL:AL, ">37",'SEPTIEMBRE 2025'!AY:AY, "EUTOCICO", 'SEPTIEMBRE 2025'!AP:AP,"SI") -> 0 | L23: =COUNTIFS('SEPTIEMBRE 2025'!AL:AL, "<28",'SEPTIEMBRE 2025'!AY:AY, "DISTOCICO", 'SEPTIEMBRE 2025'!AP:AP,"SI") -> 0 | M23: =COUNTIFS('SEPTIEMBRE 2025'!AL:AL, "<38", 'SEPTIEMBRE 2025'!AL:AL, ">27",'SEPTIEMBRE 2025'!AY:AY, "DISTOCICO", 'SEPTIEMBRE 2025'!AP:AP,"SI") -> 0 | N23: =COUNTIFS('SEPTIEMBRE 2025'!AL:AL, ">37",'SEPTIEMBRE 2025'!AY:AY, "DISTOCICO", 'SEPTIEMBRE 2025'!AP:AP,"SI") -> 0
B24: CONDUCCIÓN OXITÓCICA | D24: =SUM(I24:K24) -> 1 | E24: =I24+L24 -> 0 | F24: =J24+M24 -> 0 | G24: =K24+N24 -> 1 | I24: =COUNTIFS('SEPTIEMBRE 2025'!AL:AL, "<28",'SEPTIEMBRE 2025'!AY:AY, "EUTOCICO", 'SEPTIEMBRE 2025'!AN:AN,"SI") -> 0 | J24: =COUNTIFS('SEPTIEMBRE 2025'!AL:AL, "<38", 'SEPTIEMBRE 2025'!AL:AL, ">27", 'SEPTIEMBRE 2025'!AN:AN,"SI",'SEPTIEMBRE 2025'!AY:AY, "EUTOCICO" ) -> 0 | K24: =COUNTIFS('SEPTIEMBRE 2025'!AL:AL, ">37",'SEPTIEMBRE 2025'!AY:AY, "EUTOCICO", 'SEPTIEMBRE 2025'!AN:AN,"SI") -> 1 | L24: =COUNTIFS('SEPTIEMBRE 2025'!AL:AL, "<28",'SEPTIEMBRE 2025'!AY:AY, "DISTOCICO", 'SEPTIEMBRE 2025'!AN:AN,"SI") -> 0 | M24: =COUNTIFS('SEPTIEMBRE 2025'!AL:AL, "<38", 'SEPTIEMBRE 2025'!AL:AL, ">27", 'SEPTIEMBRE 2025'!AN:AN,"SI",'SEPTIEMBRE 2025'!AY:AY, "DISTOCICO" ) -> 0 | N24: =COUNTIFS('SEPTIEMBRE 2025'!AL:AL, ">37",'SEPTIEMBRE 2025'!AY:AY, "DISTOCICO", 'SEPTIEMBRE 2025'!AN:AN,"SI") -> 0
B25: LIBERTAD DE MOVIMIENTO | D25: =SUM(I25:K25) -> 0 | E25: =I25+L25 -> 0 | F25: =J25+M25 -> 0 | G25: =K25+N25 -> 0 | I25: =COUNTIFS('SEPTIEMBRE 2025'!AL:AL, "<28",'SEPTIEMBRE 2025'!AY:AY, "EUTOCICO", 'SEPTIEMBRE 2025'!AW:AW,"SI") -> 0 | J25: =COUNTIFS('SEPTIEMBRE 2025'!AL:AL, "<38", 'SEPTIEMBRE 2025'!AL:AL, ">27",'SEPTIEMBRE 2025'!AW:AW,"SI",'SEPTIEMBRE 2025'!AY:AY, "EUTOCICO") -> 0 | K25: =COUNTIFS('SEPTIEMBRE 2025'!AL:AL, ">37",'SEPTIEMBRE 2025'!AY:AY, "EUTOCICO", 'SEPTIEMBRE 2025'!AW:AW,"SI") -> 0 | L25: =COUNTIFS('SEPTIEMBRE 2025'!AL:AL, "<28",'SEPTIEMBRE 2025'!AY:AY, "DISTOCICO", 'SEPTIEMBRE 2025'!AW:AW,"SI") -> 0 | M25: =COUNTIFS('SEPTIEMBRE 2025'!AL:AL, "<38", 'SEPTIEMBRE 2025'!AL:AL, ">27", 'SEPTIEMBRE 2025'!AW:AW,"SI",'SEPTIEMBRE 2025'!AY:AY, "DISTOCICO") -> 0 | N25: =COUNTIFS('SEPTIEMBRE 2025'!AL:AL, ">37",'SEPTIEMBRE 2025'!AY:AY, "DISTOCICO", 'SEPTIEMBRE 2025'!AW:AW,"SI") -> 0
B26: RÉGIMEN HÍDRICO AMPLIO | D26: =SUM(I26:K26) -> 0 | E26: =I26+L26 -> 0 | F26: =J26+M26 -> 0 | G26: =K26+N26 -> 0 | I26: 0 | J26: =COUNTIFS('SEPTIEMBRE 2025'!AL:AL, "<38", 'SEPTIEMBRE 2025'!AL:AL, ">27",'SEPTIEMBRE 2025'!AY:AY, "EUTOCICO",'SEPTIEMBRE 2025'!AX:AX,"LIQUIDO") -> 0 | K26: =COUNTIFS('SEPTIEMBRE 2025'!AL:AL, ">37",'SEPTIEMBRE 2025'!AY:AY, "EUTOCICO",'SEPTIEMBRE 2025'!AX:AX,"LIQUIDO") -> 0 | L26: 0 | M26: =COUNTIFS('SEPTIEMBRE 2025'!AL:AL, "<38", 'SEPTIEMBRE 2025'!AL:AL, ">27",'SEPTIEMBRE 2025'!AY:AY, "DISTOCICO",'SEPTIEMBRE 2025'!AX:AX,"LIQUIDO") -> 0 | N26: =COUNTIFS('SEPTIEMBRE 2025'!AL:AL, ">37",'SEPTIEMBRE 2025'!AY:AY, "DISTOCICO",'SEPTIEMBRE 2025'!AX:AX,"LIQUIDO") -> 0
B27: Manejo del dolor | C27: No farmacológico | D27: =SUM(E27:G27) -> 0 | E27: =SUM(I27+L27) -> 0 | F27: =SUM(J27+M27) -> 0 | G27: =SUM(K27+N27) -> 0 | I27: =COUNTIFS('SEPTIEMBRE 2025'!AL:AL, "<28",'SEPTIEMBRE 2025'!AY:AY, "DISTOCICO", 'SEPTIEMBRE 2025'!BS:BS, "SI") -> 0 | J27: =COUNTIFS('SEPTIEMBRE 2025'!BS:BS, "SI", 'SEPTIEMBRE 2025'!AY:AY, "EUTOCICO", 'SEPTIEMBRE 2025'!AL:AL, "<38", 'SEPTIEMBRE 2025'!AL:AL, ">27") -> 0 | K27: =COUNTIFS('SEPTIEMBRE 2025'!BS:BS, "SI", 'SEPTIEMBRE 2025'!AY:AY, "EUTOCICO", 'SEPTIEMBRE 2025'!AL:AL, ">37") -> 0 | L27: =COUNTIFS('SEPTIEMBRE 2025'!AL:AL, "<28",'SEPTIEMBRE 2025'!AY:AY, "DISTOCICO", 'SEPTIEMBRE 2025'!BS:BS, "SI") -> 0 | M27: =COUNTIFS('SEPTIEMBRE 2025'!BS:BS, "SI", 'SEPTIEMBRE 2025'!AY:AY, "DISTOCICO", 'SEPTIEMBRE 2025'!AL:AL, "<38", 'SEPTIEMBRE 2025'!AL:AL, ">27") -> 0 | N27: =COUNTIFS('SEPTIEMBRE 2025'!BS:BS, "SI", 'SEPTIEMBRE 2025'!AY:AY, "DISTOCICO", 'SEPTIEMBRE 2025'!AL:AL, ">37") -> 0
C28: Farmacológico | D28: =SUM(E28:G28) -> 0 | E28: =SUM(I28+L28) -> 0 | F28: =SUM(J28+M28) -> 0 | G28: =SUM(K28+N28) -> 0 | I28: =COUNTIFS('SEPTIEMBRE 2025'!AL:AL, "<28",'SEPTIEMBRE 2025'!AY:AY, "DISTOCICO", 'SEPTIEMBRE 2025'!BS:BS, "SI") -> 0 | J28: =COUNTIFS('SEPTIEMBRE 2025'!CZ:CZ, "SI", 'SEPTIEMBRE 2025'!AY:AY, "EUTOCICO", 'SEPTIEMBRE 2025'!AL:AL, "<38", 'SEPTIEMBRE 2025'!AL:AL, ">27") -> 0 | K28: =COUNTIFS('SEPTIEMBRE 2025'!CZ:CZ, "SI", 'SEPTIEMBRE 2025'!AY:AY, "EUTOCICO", 'SEPTIEMBRE 2025'!AL:AL, ">37") -> 0 | L28: =COUNTIFS('SEPTIEMBRE 2025'!AL:AL, "<28",'SEPTIEMBRE 2025'!AY:AY, "DISTOCICO", 'SEPTIEMBRE 2025'!BS:BS, "SI") -> 0 | M28: =COUNTIFS('SEPTIEMBRE 2025'!BS:BS, "SI", 'SEPTIEMBRE 2025'!AY:AY, "DISTOCICO", 'SEPTIEMBRE 2025'!AL:AL, "<38", 'SEPTIEMBRE 2025'!AL:AL, ">27") -> 0 | N28: =COUNTIFS('SEPTIEMBRE 2025'!CZ:CZ, "SI", 'SEPTIEMBRE 2025'!AY:AY, "DISTOCICO", 'SEPTIEMBRE 2025'!AL:AL, ">37") -> 0
B29: POSICIÓN AL MOMENTO DEL EXPULSIVO | C29: LITOTOMÍA | D29: =SUM(E29:G29) -> 0 | E29: =I29+L29 -> 0 | F29: 0 | G29: 0 | I29: =COUNTIFS('SEPTIEMBRE 2025'!AL:AL, "<28",'SEPTIEMBRE 2025'!AY:AY, "EUTOCICO") -> 0 | J29: =COUNTIFS('SEPTIEMBRE 2025'!AL:AL, "<38", 'SEPTIEMBRE 2025'!AL:AL, ">27",'SEPTIEMBRE 2025'!AY:AY, "EUTOCICO",'SEPTIEMBRE 2025'!AP:AP,"NO") -> 0 | K29: =COUNTIFS('SEPTIEMBRE 2025'!AL:AL, ">37",'SEPTIEMBRE 2025'!AY:AY, "EUTOCICO", 'SEPTIEMBRE 2025'!AP:AP,"NO") -> 1 | L29: =COUNTIFS('SEPTIEMBRE 2025'!AL:AL, "<28",'SEPTIEMBRE 2025'!AY:AY, "DISTOCICO", 'SEPTIEMBRE 2025'!AP:AP,"NO") -> 0 | M29: =COUNTIFS('SEPTIEMBRE 2025'!AL:AL, "<38", 'SEPTIEMBRE 2025'!AL:AL, ">27",'SEPTIEMBRE 2025'!AY:AY, "DISTOCICO",'SEPTIEMBRE 2025'!AP:AP,"NO") -> 0 | N29: =COUNTIFS('SEPTIEMBRE 2025'!AL:AL, ">37",'SEPTIEMBRE 2025'!AY:AY, "DISTOCICO", 'SEPTIEMBRE 2025'!AP:AP,"NO") -> 0
C30: OTRAS POSICIONES | D30: =SUM(E30:G30) -> 103 | E30: =I30+L30 -> 0 | F30: 29 | G30: 74 | I30: 0 | L30: 0
B31: EPISIOTOMIA | D31: =SUM(F31:G31) -> 0 | E31: 0 | F31: 0 | G31: =COUNTIF('SEPTIEMBRE 2025'!BB:BB,"EPISIOTOMIA") -> 0 | I31: =COUNTIFS('SEPTIEMBRE 2025'!AL:AL, "<28",'SEPTIEMBRE 2025'!AY:AY, "EUTOCICO",'SEPTIEMBRE 2025'!BD:BD,"E") -> 0 | J31: =COUNTIFS('SEPTIEMBRE 2025'!AL:AL, "<38", 'SEPTIEMBRE 2025'!AL:AL, ">27",'SEPTIEMBRE 2025'!AY:AY, "EUTOCICO",'SEPTIEMBRE 2025'!BD:BD,"E") -> 0 | K31: =COUNTIFS('SEPTIEMBRE 2025'!AL:AL, ">37",'SEPTIEMBRE 2025'!AY:AY, "EUTOCICO",'SEPTIEMBRE 2025'!BD:BD,"E") -> 0 | L31: =COUNTIFS('SEPTIEMBRE 2025'!AL:AL, "<28",'SEPTIEMBRE 2025'!AY:AY, "DISTOCICO",'SEPTIEMBRE 2025'!BD:BD,"E") -> 0 | M31: =COUNTIFS('SEPTIEMBRE 2025'!AL:AL, "<38", 'SEPTIEMBRE 2025'!AL:AL, ">27",'SEPTIEMBRE 2025'!AY:AY, "DISTOCICO",'SEPTIEMBRE 2025'!BD:BD,"E") -> 0 | N31: =COUNTIFS('SEPTIEMBRE 2025'!AL:AL, ">37",'SEPTIEMBRE 2025'!AY:AY, "DISTOCICO",'SEPTIEMBRE 2025'!BD:BD,"E") -> 0
B32: ACOMPAÑAMIENTO | C32: DURANTE EL TRABAJO DE PARTO | D32: =SUM(I32:K32) -> 0 | E32: =SUM(I32+L32) -> 0 | F32: =SUM(J32+M32) -> 0 | G32: =SUM(K32+N32) -> 0 | I32: 0 | J32: =COUNTIFS('SEPTIEMBRE 2025'!AL:AL, "<38", 'SEPTIEMBRE 2025'!AL:AL, ">27",'SEPTIEMBRE 2025'!AY:AY, "EUTOCICO",'SEPTIEMBRE 2025'!CJ:CJ,"SI") -> 0 | K32: =COUNTIFS('SEPTIEMBRE 2025'!AL:AL, ">37",'SEPTIEMBRE 2025'!AY:AY, "EUTOCICO",'SEPTIEMBRE 2025'!CJ:CJ,"SI") -> 0 | L32: 0 | M32: =COUNTIFS('SEPTIEMBRE 2025'!AL:AL, "<38", 'SEPTIEMBRE 2025'!AL:AL, ">27",'SEPTIEMBRE 2025'!AY:AY, "DISTOCICO",'SEPTIEMBRE 2025'!CJ:CJ,"SI") -> 0 | N32: =COUNTIFS('SEPTIEMBRE 2025'!AL:AL, ">37",'SEPTIEMBRE 2025'!AY:AY, "DISTOCICO",'SEPTIEMBRE 2025'!CJ:CJ,"SI") -> 0
C33: SOLO EN EL EXPULSIVO | D33: =SUM(I33:K33) -> 1 | E33: =SUM(I33+L33) -> 0 | F33: =SUM(J33+M33) -> 0 | G33: =SUM(K33+N33) -> 1 | I33: 0 | J33: =COUNTIFS('SEPTIEMBRE 2025'!AL:AL, "<38", 'SEPTIEMBRE 2025'!AL:AL, ">27",'SEPTIEMBRE 2025'!AY:AY, "EUTOCICO",'SEPTIEMBRE 2025'!CK:CK,"SI") -> 0 | K33: =COUNTIFS('SEPTIEMBRE 2025'!AL:AL, ">37",'SEPTIEMBRE 2025'!AY:AY, "EUTOCICO",'SEPTIEMBRE 2025'!CK:CK,"SI") -> 1 | L33: 0 | M33: =COUNTIFS('SEPTIEMBRE 2025'!AL:AL, "<38", 'SEPTIEMBRE 2025'!AL:AL, ">27",'SEPTIEMBRE 2025'!AY:AY, "DISTOCICO",'SEPTIEMBRE 2025'!CK:CK,"SI") -> 0 | N33: =COUNTIFS('SEPTIEMBRE 2025'!AL:AL, ">37",'SEPTIEMBRE 2025'!AY:AY, "DISTOCICO",'SEPTIEMBRE 2025'!CK:CK,"SI") -> 0
B35: SECCIÓN G: ESTERILIZACIONES QUIRÚRGICAS
B36: SEXO | C36: TOTAL | D36: EDAD (en años) | G36: Trans | J36: REM A 21
D37: Menor de 20 años | E37: 20 - 34 años | F37: 35 y más años | G37: Masculino | H37: Femenino
B38: MUJER | C38: =SUM(D38:F38) -> 5 | D38: =COUNTIFS('SEPTIEMBRE 2025'!N:N, "<20",'SEPTIEMBRE 2025'!BE:BE, "SI") -> 0 | E38: =COUNTIFS('SEPTIEMBRE 2025'!N:N, ">19",'SEPTIEMBRE 2025'!N:N, "<35",'SEPTIEMBRE 2025'!BE:BE, "SI")+2 -> 2 | F38: =COUNTIFS('SEPTIEMBRE 2025'!N:N, ">34",'SEPTIEMBRE 2025'!BE:BE, "SI")+3 -> 3 | G38: 0 | H38: 0 | I38: *
B39: HOMBRE | C39: =SUM(D39:F39) -> 0
B41: * Corrección de dato con planilla de cirugias ginecologicas
B44: TIPO DE COMPLICACIÓN | D44: Atención institucional | G44: Parto en domicilio | J44: Cesárea | M44: Eutocicos | O44: Distocicos
D45: Parto Espontaneo | E45: Parto Inducido | F45: Cesárea | J45: Urgencia | K45: Electiva | M45: Espontaneo | N45: Inducido | O45: Espontaneo | P45: Inducido
B46: Hemorragia post parto | C46: Inercia | D46: =M46+O46 -> 0 | E46: =COUNTIFS('SEPTIEMBRE 2025'!BE:BE, "SI",'SEPTIEMBRE 2025'!B:B, "INSTITUCIONAL", 'SEPTIEMBRE 2025'!AP:AP,"si", 'SEPTIEMBRE 2025'!AP:AP,"SI") -> 0 | F46: =SUM(J46:K46) -> 0 | G46: 0 | J46: =COUNTIFS('SEPTIEMBRE 2025'!BG:BG, "SI",'SEPTIEMBRE 2025'!B:B, "INSTITUCIONAL", 'SEPTIEMBRE 2025'!AY:AY, "CES. URGENCIA") -> 0 | K46: =COUNTIFS('SEPTIEMBRE 2025'!BG:BG, "SI",'SEPTIEMBRE 2025'!B:B, "INSTITUCIONAL",'SEPTIEMBRE 2025'!AY:AY, "CES.ELECTIVA") -> 0 | M46: =COUNTIFS('SEPTIEMBRE 2025'!AY:AY, "EUTOCICO", 'SEPTIEMBRE 2025'!AP:AP,"NO", 'SEPTIEMBRE 2025'!BE:BE, "SI",'SEPTIEMBRE 2025'!B:B, "INSTITUCIONAL", 'SEPTIEMBRE 2025'!AP:AP,"NO") -> 0 | N46: =COUNTIFS('SEPTIEMBRE 2025'!AY:AY, "EUTOCICO", 'SEPTIEMBRE 2025'!AP:AP,"SI", 'SEPTIEMBRE 2025'!BE:BE, "SI",'SEPTIEMBRE 2025'!B:B, "INSTITUCIONAL", 'SEPTIEMBRE 2025'!AP:AP,"NO") -> 0 | O46: =COUNTIFS('SEPTIEMBRE 2025'!AY:AY, "DISTOCICO", 'SEPTIEMBRE 2025'!AP:AP,"NO", 'SEPTIEMBRE 2025'!BE:BE, "SI",'SEPTIEMBRE 2025'!B:B, "INSTITUCIONAL", 'SEPTIEMBRE 2025'!AP:AP,"NO") -> 0 | P46: =COUNTIFS('SEPTIEMBRE 2025'!AY:AY, "DISTOCICO", 'SEPTIEMBRE 2025'!AP:AP,"SI", 'SEPTIEMBRE 2025'!BE:BE, "SI",'SEPTIEMBRE 2025'!B:B, "INSTITUCIONAL", 'SEPTIEMBRE 2025'!AP:AP,"NO") -> 0
C47: Restos | D47: =M47+O47 -> 1 | E47: =N47+P47 -> 0 | F47: =SUM(J47:K47) -> 0 | G47: 0 | J47: =COUNTIFS('SEPTIEMBRE 2025'!BH:BH, "SI",'SEPTIEMBRE 2025'!B:B, "INSTITUCIONAL", 'SEPTIEMBRE 2025'!AY:AY, "CES. URGENCIA") -> 0 | K47: =COUNTIFS('SEPTIEMBRE 2025'!BH:BH, "SI",'SEPTIEMBRE 2025'!B:B, "INSTITUCIONAL",'SEPTIEMBRE 2025'!AY:AY, "CES.ELECTIVA") -> 0 | M47: =COUNTIFS('SEPTIEMBRE 2025'!BF:BF, "SI",'SEPTIEMBRE 2025'!B:B, "INSTITUCIONAL", 'SEPTIEMBRE 2025'!AP:AP,"NO", 'SEPTIEMBRE 2025'!AY:AY, "EUTOCICO") -> 1 | N47: =COUNTIFS('SEPTIEMBRE 2025'!BF:BF, "SI",'SEPTIEMBRE 2025'!B:B, "INSTITUCIONAL", 'SEPTIEMBRE 2025'!AP:AP,"SI", 'SEPTIEMBRE 2025'!AY:AY, "EUTOCICO") -> 0 | O47: =COUNTIFS('SEPTIEMBRE 2025'!BF:BF, "SI",'SEPTIEMBRE 2025'!B:B, "INSTITUCIONAL", 'SEPTIEMBRE 2025'!AP:AP,"NO", 'SEPTIEMBRE 2025'!AY:AY, "DISTOCICO") -> 0 | P47: =COUNTIFS('SEPTIEMBRE 2025'!BF:BF, "SI",'SEPTIEMBRE 2025'!B:B, "INSTITUCIONAL", 'SEPTIEMBRE 2025'!AP:AP,"SI", 'SEPTIEMBRE 2025'!AY:AY, "DISTOCICO") -> 0
...

Sheet APS
B3: Fecha | C3: Hora | D3: Nombre | E3: R.U.T. | F3: DV | G3: CONSULTORIO | H3: TIPO DE PARTO | I3: PESO | J3: TALLA | K3: APGAR AL 1 | L3: APGAR 5 | M3: APEGO
B4: ='SEPTIEMBRE 2025'!D4 -> 45901 | C4: ='SEPTIEMBRE 2025'!E4 -> 0.41388889 | D4: ='SEPTIEMBRE 2025'!H4 -> NICOLE ANGELA FLORES ZAPATA | E4: ='SEPTIEMBRE 2025'!I4 -> 11111111 | F4: ='SEPTIEMBRE 2025'!J4 -> 0 | G4: ='SEPTIEMBRE 2025'!U4 -> FEDERICO PUGA | H4: ='SEPTIEMBRE 2025'!AY4 -> EUTOCICO | I4: ='SEPTIEMBRE 2025'!CC4 -> 3450 | J4: ='SEPTIEMBRE 2025'!CD4 -> 50 | K4: ='SEPTIEMBRE 2025'!CF4 -> 8 | L4: ='SEPTIEMBRE 2025'!CG4 -> 9 | M4: ='SEPTIEMBRE 2025'!CH4 -> 4
B5: ='SEPTIEMBRE 2025'!D5 -> 0 | C5: ='SEPTIEMBRE 2025'!E5 -> 0 | D5: ='SEPTIEMBRE 2025'!H5 -> 0 | E5: ='SEPTIEMBRE 2025'!I5 -> 0 | F5: ='SEPTIEMBRE 2025'!J5 -> 0 | G5: ='SEPTIEMBRE 2025'!U5 -> 0 | H5: ='SEPTIEMBRE 2025'!AY5 -> DISTOCICO | I5: ='SEPTIEMBRE 2025'!CC5 -> 3350 | J5: ='SEPTIEMBRE 2025'!CD5 -> 50 | K5: ='SEPTIEMBRE 2025'!CF5 -> 8 | L5: ='SEPTIEMBRE 2025'!CG5 -> 9 | M5: ='SEPTIEMBRE 2025'!CH5 -> 4
B6: ='SEPTIEMBRE 2025'!D6 -> 0 | C6: ='SEPTIEMBRE 2025'!E6 -> 0 | D6: ='SEPTIEMBRE 2025'!H6 -> 0 | E6: ='SEPTIEMBRE 2025'!I6 -> 0 | F6: ='SEPTIEMBRE 2025'!J6 -> 0 | G6: ='SEPTIEMBRE 2025'!U6 -> 0 | H6: ='SEPTIEMBRE 2025'!AY6 -> CES. URGENCIA | I6: ='SEPTIEMBRE 2025'!CC6 -> 0 | J6: ='SEPTIEMBRE 2025'!CD6 -> 0 | K6: ='SEPTIEMBRE 2025'!CF6 -> 0 | L6: ='SEPTIEMBRE 2025'!CG6 -> 0 | M6: ='SEPTIEMBRE 2025'!CH6 -> 0
B7: ='SEPTIEMBRE 2025'!D7 -> 0 | C7: ='SEPTIEMBRE 2025'!E7 -> 0 | D7: ='SEPTIEMBRE 2025'!H7 -> 0 | E7: ='SEPTIEMBRE 2025'!I7 -> 0 | F7: ='SEPTIEMBRE 2025'!J7 -> 0 | G7: ='SEPTIEMBRE 2025'!U7 -> 0 | H7: ='SEPTIEMBRE 2025'!AY7 -> CES.ELECTIVA | I7: ='SEPTIEMBRE 2025'!CC7 -> 0 | J7: ='SEPTIEMBRE 2025'!CD7 -> 0 | K7: ='SEPTIEMBRE 2025'!CF7 -> 0 | L7: ='SEPTIEMBRE 2025'!CG7 -> 0 | M7: ='SEPTIEMBRE 2025'!CH7 -> 0
B8: ='SEPTIEMBRE 2025'!D8 -> 0 | C8: ='SEPTIEMBRE 2025'!E8 -> 0 | D8: ='SEPTIEMBRE 2025'!H8 -> 0 | E8: ='SEPTIEMBRE 2025'!I8 -> 0 | F8: ='SEPTIEMBRE 2025'!J8 -> 0 | G8: ='SEPTIEMBRE 2025'!U8 -> 0 | H8: ='SEPTIEMBRE 2025'!AY8 -> 0 | I8: ='SEPTIEMBRE 2025'!CC8 -> 0 | J8: ='SEPTIEMBRE 2025'!CD8 -> 0 | K8: ='SEPTIEMBRE 2025'!CF8 -> 0 | L8: ='SEPTIEMBRE 2025'!CG8 -> 0 | M8: ='SEPTIEMBRE 2025'!CH8 -> 0
B9: ='SEPTIEMBRE 2025'!D9 -> 0 | C9: ='SEPTIEMBRE 2025'!E9 -> 0 | D9: ='SEPTIEMBRE 2025'!H9 -> 0 | E9: ='SEPTIEMBRE 2025'!I9 -> 0 | F9: ='SEPTIEMBRE 2025'!J9 -> 0 | G9: ='SEPTIEMBRE 2025'!U9 -> 0 | H9: ='SEPTIEMBRE 2025'!AY9 -> 0 | I9: ='SEPTIEMBRE 2025'!CC9 -> 0 | J9: ='SEPTIEMBRE 2025'!CD9 -> 0 | K9: ='SEPTIEMBRE 2025'!CF9 -> 0 | L9: ='SEPTIEMBRE 2025'!CG9 -> 0 | M9: ='SEPTIEMBRE 2025'!CH9 -> 0
B10: ='SEPTIEMBRE 2025'!D10 -> 0 | C10: ='SEPTIEMBRE 2025'!E10 -> 0 | D10: ='SEPTIEMBRE 2025'!H10 -> 0 | E10: ='SEPTIEMBRE 2025'!I10 -> 0 | F10: ='SEPTIEMBRE 2025'!J10 -> 0 | G10: ='SEPTIEMBRE 2025'!U10 -> 0 | H10: ='SEPTIEMBRE 2025'!AY10 -> 0 | I10: ='SEPTIEMBRE 2025'!CC10 -> 0 | J10: ='SEPTIEMBRE 2025'!CD10 -> 0 | K10: ='SEPTIEMBRE 2025'!CF10 -> 0 | L10: ='SEPTIEMBRE 2025'!CG10 -> 0 | M10: ='SEPTIEMBRE 2025'!CH10 -> 0
B11: ='SEPTIEMBRE 2025'!D11 -> 0 | C11: ='SEPTIEMBRE 2025'!E11 -> 0 | D11: ='SEPTIEMBRE 2025'!H11 -> 0 | E11: ='SEPTIEMBRE 2025'!I11 -> 0 | F11: ='SEPTIEMBRE 2025'!J11 -> 0 | G11: ='SEPTIEMBRE 2025'!U11 -> 0 | H11: ='SEPTIEMBRE 2025'!AY11 -> 0 | I11: ='SEPTIEMBRE 2025'!CC11 -> 0 | J11: ='SEPTIEMBRE 2025'!CD11 -> 0 | K11: ='SEPTIEMBRE 2025'!CF11 -> 0 | L11: ='SEPTIEMBRE 2025'!CG11 -> 0 | M11: ='SEPTIEMBRE 2025'!CH11 -> 0
B12: ='SEPTIEMBRE 2025'!D12 -> 0 | C12: ='SEPTIEMBRE 2025'!E12 -> 0 | D12: ='SEPTIEMBRE 2025'!H12 -> 0 | E12: ='SEPTIEMBRE 2025'!I12 -> 0 | F12: ='SEPTIEMBRE 2025'!J12 -> 0 | G12: ='SEPTIEMBRE 2025'!U12 -> 0 | H12: ='SEPTIEMBRE 2025'!AY12 -> 0 | I12: ='SEPTIEMBRE 2025'!CC12 -> 0 | J12: ='SEPTIEMBRE 2025'!CD12 -> 0 | K12: ='SEPTIEMBRE 2025'!CF12 -> 0 | L12: ='SEPTIEMBRE 2025'!CG12 -> 0 | M12: ='SEPTIEMBRE 2025'!CH12 -> 0
B13: ='SEPTIEMBRE 2025'!D13 -> 0 | C13: ='SEPTIEMBRE 2025'!E13 -> 0 | D13: ='SEPTIEMBRE 2025'!H13 -> 0 | E13: ='SEPTIEMBRE 2025'!I13 -> 0 | F13: ='SEPTIEMBRE 2025'!J13 -> 0 | G13: ='SEPTIEMBRE 2025'!U13 -> 0 | H13: ='SEPTIEMBRE 2025'!AY13 -> 0 | I13: ='SEPTIEMBRE 2025'!CC13 -> 0 | J13: ='SEPTIEMBRE 2025'!CD13 -> 0 | K13: ='SEPTIEMBRE 2025'!CF13 -> 0 | L13: ='SEPTIEMBRE 2025'!CG13 -> 0 | M13: ='SEPTIEMBRE 2025'!CH13 -> 0
B14: ='SEPTIEMBRE 2025'!D14 -> 0 | C14: ='SEPTIEMBRE 2025'!E14 -> 0 | D14: ='SEPTIEMBRE 2025'!H14 -> 0 | E14: ='SEPTIEMBRE 2025'!I14 -> 0 | F14: ='SEPTIEMBRE 2025'!J14 -> 0 | G14: ='SEPTIEMBRE 2025'!U14 -> 0 | H14: ='SEPTIEMBRE 2025'!AY14 -> 0 | I14: ='SEPTIEMBRE 2025'!CC14 -> 0 | J14: ='SEPTIEMBRE 2025'!CD14 -> 0 | K14: ='SEPTIEMBRE 2025'!CF14 -> 0 | L14: ='SEPTIEMBRE 2025'!CG14 -> 0 | M14: ='SEPTIEMBRE 2025'!CH14 -> 0
B15: ='SEPTIEMBRE 2025'!D15 -> 0 | C15: ='SEPTIEMBRE 2025'!E15 -> 0 | D15: ='SEPTIEMBRE 2025'!H15 -> 0 | E15: ='SEPTIEMBRE 2025'!I15 -> 0 | F15: ='SEPTIEMBRE 2025'!J15 -> 0 | G15: ='SEPTIEMBRE 2025'!U15 -> 0 | H15: ='SEPTIEMBRE 2025'!AY15 -> 0 | I15: ='SEPTIEMBRE 2025'!CC15 -> 0 | J15: ='SEPTIEMBRE 2025'!CD15 -> 0 | K15: ='SEPTIEMBRE 2025'!CF15 -> 0 | L15: ='SEPTIEMBRE 2025'!CG15 -> 0 | M15: ='SEPTIEMBRE 2025'!CH15 -> 0
... B38: ='SEPTIEMBRE 2025'!D38 -> 0 | C38: ='SEPTIEMBRE 2025'!E38 -> 0 | D38: ='SEPTIEMBRE 2025'!H38 -> 0 | E38: ='SEPTIEMBRE 2025'!I38 -> 0 | F38: ='SEPTIEMBRE 2025'!J38 -> 0 | G38: ='SEPTIEMBRE 2025'!U38 -> 0 | H38: ='SEPTIEMBRE 2025'!AY38 -> 0 | I38: ='SEPTIEMBRE 2025'!CC38 -> 0 | J38: ='SEPTIEMBRE 2025'!CD38 -> 0 | K38: ='SEPTIEMBRE 2025'!CF38 -> 0 | L38: ='SEPTIEMBRE 2025'!CG38 -> 0 | M38: ='SEPTIEMBRE 2025'!CH38 -> 0
B39: ='SEPTIEMBRE 2025'!D39 -> 0 | C39: ='SEPTIEMBRE 2025'!E39 -> 0 | D39: ='SEPTIEMBRE 2025'!H39 -> 0 | E39: ='SEPTIEMBRE 2025'!I39 -> 0 | F39: ='SEPTIEMBRE 2025'!J39 -> 0 | G39: ='SEPTIEMBRE 2025'!U39 -> 0 | H39: ='SEPTIEMBRE 2025'!AY41 -> 0 | I39: ='SEPTIEMBRE 2025'!CC39 -> 0 | J39: ='SEPTIEMBRE 2025'!CD39 -> 0 | K39: ='SEPTIEMBRE 2025'!CF39 -> 0 | L39: ='SEPTIEMBRE 2025'!CG39 -> 0 | M39: ='SEPTIEMBRE 2025'!CH39 -> 0
B40: ='SEPTIEMBRE 2025'!D40 -> 0 | C40: ='SEPTIEMBRE 2025'!E40 -> 0 | D40: ='SEPTIEMBRE 2025'!H40 -> 0 | E40: ='SEPTIEMBRE 2025'!I40 -> 0 | F40: ='SEPTIEMBRE 2025'!J40 -> 0 | G40: ='SEPTIEMBRE 2025'!U40 -> 0 | H40: ='SEPTIEMBRE 2025'!AY40 -> 0 | I40: ='SEPTIEMBRE 2025'!CC40 -> 0 | J40: ='SEPTIEMBRE 2025'!CD40 -> 0 | K40: ='SEPTIEMBRE 2025'!CF40 -> 0 | L40: ='SEPTIEMBRE 2025'!CG40 -> 0 | M40: ='SEPTIEMBRE 2025'!CH40 -> 0
B41: ='SEPTIEMBRE 2025'!D41 -> 0 | C41: ='SEPTIEMBRE 2025'!E41 -> 0 | D41: ='SEPTIEMBRE 2025'!H41 -> 0 | E41: ='SEPTIEMBRE 2025'!I41 -> 0 | F41: ='SEPTIEMBRE 2025'!J41 -> 0 | G41: ='SEPTIEMBRE 2025'!U41 -> 0 | H41: ='SEPTIEMBRE 2025'!#REF! -> #REF! | I41: ='SEPTIEMBRE 2025'!CC41 -> 0 | J41: ='SEPTIEMBRE 2025'!CD41 -> 0 | K41: ='SEPTIEMBRE 2025'!CF41 -> 0 | L41: ='SEPTIEMBRE 2025'!CG41 -> 0 | M41: ='SEPTIEMBRE 2025'!CH41 -> 0
B42: ='SEPTIEMBRE 2025'!D42 -> 0 | C42: ='SEPTIEMBRE 2025'!E42 -> 0 | D42: ='SEPTIEMBRE 2025'!H42 -> 0 | E42: ='SEPTIEMBRE 2025'!I42 -> 0 | F42: ='SEPTIEMBRE 2025'!J42 -> 0 | G42: ='SEPTIEMBRE 2025'!U42 -> 0 | H42: ='SEPTIEMBRE 2025'!AY42 -> 0 | I42: ='SEPTIEMBRE 2025'!CC42 -> 0 | J42: ='SEPTIEMBRE 2025'!CD42 -> 0 | K42: ='SEPTIEMBRE 2025'!CF42 -> 0 | L42: ='SEPTIEMBRE 2025'!CG42 -> 0 | M42: ='SEPTIEMBRE 2025'!CH42 -> 0
B43: ='SEPTIEMBRE 2025'!D43 -> 0 | C43: ='SEPTIEMBRE 2025'!E43 -> 0 | D43: ='SEPTIEMBRE 2025'!H43 -> 0 | E43: ='SEPTIEMBRE 2025'!I43 -> 0 | F43: ='SEPTIEMBRE 2025'!J43 -> 0 | G43: ='SEPTIEMBRE 2025'!U43 -> 0 | H43: ='SEPTIEMBRE 2025'!AY43 -> 0 | I43: ='SEPTIEMBRE 2025'!CC43 -> 0 | J43: ='SEPTIEMBRE 2025'!CD43 -> 0 | K43: ='SEPTIEMBRE 2025'!CF43 -> 0 | L43: ='SEPTIEMBRE 2025'!CG43 -> 0 | M43: ='SEPTIEMBRE 2025'!CH43 -> 0
B44: ='SEPTIEMBRE 2025'!D44 -> 0 | C44: ='SEPTIEMBRE 2025'!E44 -> 0 | D44: ='SEPTIEMBRE 2025'!H44 -> 0 | E44: ='SEPTIEMBRE 2025'!I44 -> 0 | F44: ='SEPTIEMBRE 2025'!J44 -> 0 | G44: ='SEPTIEMBRE 2025'!U44 -> 0 | H44: ='SEPTIEMBRE 2025'!AY44 -> 0 | I44: ='SEPTIEMBRE 2025'!CC44 -> 0 | J44: ='SEPTIEMBRE 2025'!CD44 -> 0 | K44: ='SEPTIEMBRE 2025'!CF44 -> 0 | L44: ='SEPTIEMBRE 2025'!CG44 -> 0 | M44: ='SEPTIEMBRE 2025'!CH44 -> 0
B45: ='SEPTIEMBRE 2025'!D45 -> 0 | C45: ='SEPTIEMBRE 2025'!E45 -> 0 | D45: ='SEPTIEMBRE 2025'!H45 -> 0 | E45: ='SEPTIEMBRE 2025'!I45 -> 0 | F45: ='SEPTIEMBRE 2025'!J45 -> 0 | G45: ='SEPTIEMBRE 2025'!U45 -> 0 | H45: ='SEPTIEMBRE 2025'!AY45 -> 0 | I45: ='SEPTIEMBRE 2025'!CC45 -> 0 | J45: ='SEPTIEMBRE 2025'!CD45 -> 0 | K45: ='SEPTIEMBRE 2025'!CF45 -> 0 | L45: ='SEPTIEMBRE 2025'!CG45 -> 0 | M45: ='SEPTIEMBRE 2025'!CH45 -> 0
B46: ='SEPTIEMBRE 2025'!D46 -> 0 | C46: ='SEPTIEMBRE 2025'!E46 -> 0 | D46: ='SEPTIEMBRE 2025'!H46 -> 0 | E46: ='SEPTIEMBRE 2025'!I46 -> 0 | F46: ='SEPTIEMBRE 2025'!J46 -> 0 | G46: ='SEPTIEMBRE 2025'!U46 -> 0 | H46: ='SEPTIEMBRE 2025'!AY46 -> 0 | I46: ='SEPTIEMBRE 2025'!CC46 -> 0 | J46: ='SEPTIEMBRE 2025'!CD46 -> 0 | K46: ='SEPTIEMBRE 2025'!CF46 -> 0 | L46: ='SEPTIEMBRE 2025'!CG46 -> 0 | M46: ='SEPTIEMBRE 2025'!CH46 -> 0
B47: ='SEPTIEMBRE 2025'!D47 -> 0 | C47: ='SEPTIEMBRE 2025'!E47 -> 0 | D47: ='SEPTIEMBRE 2025'!H47 -> 0 | E47: ='SEPTIEMBRE 2025'!I47 -> 0 | F47: ='SEPTIEMBRE 2025'!J47 -> 0 | G47: ='SEPTIEMBRE 2025'!U47 -> 0 | H47: ='SEPTIEMBRE 2025'!AY47 -> 0 | I47: ='SEPTIEMBRE 2025'!CC47 -> 0 | J47: ='SEPTIEMBRE 2025'!CD47 -> 0 | K47: ='SEPTIEMBRE 2025'!CF47 -> 0 | L47: ='SEPTIEMBRE 2025'!CG47 -> 0 | M47: ='SEPTIEMBRE 2025'!CH47 -> 0
B48: ='SEPTIEMBRE 2025'!D48 -> 0 | C48: ='SEPTIEMBRE 2025'!E48 -> 0 | D48: ='SEPTIEMBRE 2025'!H48 -> 0 | E48: ='SEPTIEMBRE 2025'!I48 -> 0 | F48: ='SEPTIEMBRE 2025'!J48 -> 0 | G48: ='SEPTIEMBRE 2025'!U48 -> 0 | H48: ='SEPTIEMBRE 2025'!AY48 -> 0 | I48: ='SEPTIEMBRE 2025'!CC48 -> 0 | J48: ='SEPTIEMBRE 2025'!CD48 -> 0 | K48: ='SEPTIEMBRE 2025'!CF48 -> 0 | L48: ='SEPTIEMBRE 2025'!CG48 -> 0 | M48: ='SEPTIEMBRE 2025'!CH48 -> 0
B49: ='SEPTIEMBRE 2025'!D49 -> 0 | C49: ='SEPTIEMBRE 2025'!E49 -> 0 | D49: ='SEPTIEMBRE 2025'!H49 -> 0 | E49: ='SEPTIEMBRE 2025'!I49 -> 0 | F49: ='SEPTIEMBRE 2025'!J49 -> 0 | G49: ='SEPTIEMBRE 2025'!U49 -> 0 | H49: ='SEPTIEMBRE 2025'!AY49 -> 0 | I49: ='SEPTIEMBRE 2025'!CC49 -> 0 | J49: ='SEPTIEMBRE 2025'!CD49 -> 0 | K49: ='SEPTIEMBRE 2025'!CF49 -> 0 | L49: ='SEPTIEMBRE 2025'!CG49 -> 0 | M49: ='SEPTIEMBRE 2025'!CH49 -> 0
B50: ='SEPTIEMBRE 2025'!D50 -> 0 | C50: ='SEPTIEMBRE 2025'!E50 -> 0 | D50: ='SEPTIEMBRE 2025'!H50 -> 0 | E50: ='SEPTIEMBRE 2025'!I50 -> 0 | F50: ='SEPTIEMBRE 2025'!J50 -> 0 | G50: ='SEPTIEMBRE 2025'!U50 -> 0 | H50: ='SEPTIEMBRE 2025'!AY50 -> 0 | I50: ='SEPTIEMBRE 2025'!CC50 -> 0 | J50: ='SEPTIEMBRE 2025'!CD50 -> 0 | K50: ='SEPTIEMBRE 2025'!CF50 -> 0 | L50: ='SEPTIEMBRE 2025'!CG50 -> 0 | M50: ='SEPTIEMBRE 2025'!CH50 -> 0
B51: ='SEPTIEMBRE 2025'!D51 -> 0 | C51: ='SEPTIEMBRE 2025'!E51 -> 0 | D51: ='SEPTIEMBRE 2025'!H51 -> 0 | E51: ='SEPTIEMBRE 2025'!I51 -> 0 | F51: ='SEPTIEMBRE 2025'!J51 -> 0 | G51: ='SEPTIEMBRE 2025'!U51 -> 0 | H51: ='SEPTIEMBRE 2025'!AY51 -> 0 | I51: ='SEPTIEMBRE 2025'!CC51 -> 0 | J51: ='SEPTIEMBRE 2025'!CD51 -> 0 | K51: ='SEPTIEMBRE 2025'!CF51 -> 0 | L51: ='SEPTIEMBRE 2025'!CG51 -> 0 | M51: ='SEPTIEMBRE 2025'!CH51 -> 0
B52: ='SEPTIEMBRE 2025'!D52 -> 0 | C52: ='SEPTIEMBRE 2025'!E52 -> 0 | D52: ='SEPTIEMBRE 2025'!H52 -> 0 | E52: ='SEPTIEMBRE 2025'!I52 -> 0 | F52: ='SEPTIEMBRE 2025'!J52 -> 0 | G52: ='SEPTIEMBRE 2025'!U52 -> 0 | H52: ='SEPTIEMBRE 2025'!AY52 -> 0 | I52: ='SEPTIEMBRE 2025'!CC52 -> 0 | J52: ='SEPTIEMBRE 2025'!CD52 -> 0 | K52: ='SEPTIEMBRE 2025'!CF52 -> 0 | L52: ='SEPTIEMBRE 2025'!CG52 -> 0 | M52: ='SEPTIEMBRE 2025'!CH52 -> 0
B53: ='SEPTIEMBRE 2025'!D53 -> 0 | C53: ='SEPTIEMBRE 2025'!E53 -> 0 | D53: ='SEPTIEMBRE 2025'!H53 -> 0 | E53: ='SEPTIEMBRE 2025'!I53 -> 0 | F53: ='SEPTIEMBRE 2025'!J53 -> 0 | G53: ='SEPTIEMBRE 2025'!U53 -> 0 | H53: ='SEPTIEMBRE 2025'!AY53 -> 0 | I53: ='SEPTIEMBRE 2025'!CC53 -> 0 | J53: ='SEPTIEMBRE 2025'!CD53 -> 0 | K53: ='SEPTIEMBRE 2025'!CF53 -> 0 | L53: ='SEPTIEMBRE 2025'!CG53 -> 0 | M53: ='SEPTIEMBRE 2025'!CH53 -> 0
B54: ='SEPTIEMBRE 2025'!D54 -> 0 | C54: ='SEPTIEMBRE 2025'!E54 -> 0 | D54: ='SEPTIEMBRE 2025'!H54 -> 0 | E54: ='SEPTIEMBRE 2025'!I54 -> 0 | F54: ='SEPTIEMBRE 2025'!J54 -> 0 | G54: ='SEPTIEMBRE 2025'!U54 -> 0 | H54: ='SEPTIEMBRE 2025'!AY54 -> 0 | I54: ='SEPTIEMBRE 2025'!CC54 -> 0 | J54: ='SEPTIEMBRE 2025'!CD54 -> 0 | K54: ='SEPTIEMBRE 2025'!CF54 -> 0 | L54: ='SEPTIEMBRE 2025'!CG54 -> 0 | M54: ='SEPTIEMBRE 2025'!CH54 -> 0
B55: ='SEPTIEMBRE 2025'!I56 -> 0 | C55: ='SEPTIEMBRE 2025'!J56 -> 0 | D55: ='SEPTIEMBRE 2025'!M56 -> 0 | E55: ='SEPTIEMBRE 2025'!N56 -> 0 | F55: ='SEPTIEMBRE 2025'!O56 -> 0 | G55: ='SEPTIEMBRE 2025'!Z56 -> 0 | H55: ='SEPTIEMBRE 2025'!BD56 -> 0 | I55: ='SEPTIEMBRE 2025'!CH56 -> 0 | J55: ='SEPTIEMBRE 2025'!CI56 -> 0 | K55: ='SEPTIEMBRE 2025'!CK56 -> 0 | L55: ='SEPTIEMBRE 2025'!CL56 -> 0 | M55: ='SEPTIEMBRE 2025'!CM56 -> 0
B56: ='SEPTIEMBRE 2025'!I57 -> 0 | C56: ='SEPTIEMBRE 2025'!J57 -> 0 | D56: ='SEPTIEMBRE 2025'!M57 -> 0 | E56: ='SEPTIEMBRE 2025'!N57 -> 0 | F56: ='SEPTIEMBRE 2025'!O57 -> 0 | G56: ='SEPTIEMBRE 2025'!Z57 -> 0 | H56: ='SEPTIEMBRE 2025'!BD57 -> 0 | I56: ='SEPTIEMBRE 2025'!CH57 -> 0 | J56: ='SEPTIEMBRE 2025'!CI57 -> 0 | K56: ='SEPTIEMBRE 2025'!CK57 -> 0 | L56: ='SEPTIEMBRE 2025'!CL57 -> 0 | M56: ='SEPTIEMBRE 2025'!CM57 -> 0
B57: ='SEPTIEMBRE 2025'!#REF! -> #REF! | C57: ='SEPTIEMBRE 2025'!#REF! -> #REF! | D57: ='SEPTIEMBRE 2025'!#REF! -> #REF! | E57: ='SEPTIEMBRE 2025'!#REF! -> #REF! | F57: ='SEPTIEMBRE 2025'!#REF! -> #REF! | G57: ='SEPTIEMBRE 2025'!#REF! -> #REF! | H57: ='SEPTIEMBRE 2025'!#REF! -> #REF! | I57: ='SEPTIEMBRE 2025'!#REF! -> #REF! | ... M57: ='SEPTIEMBRE 2025'!#REF! -> #REF!
B58: ='SEPTIEMBRE 2025'!D58 -> 0 | C58: ='SEPTIEMBRE 2025'!E58 -> 0 | D58: ='SEPTIEMBRE 2025'!H58 -> 0 | E58: ='SEPTIEMBRE 2025'!I58 -> 0 | F58: ='SEPTIEMBRE 2025'!J58 -> 0 | G58: ='SEPTIEMBRE 2025'!U58 -> 0 | H58: ='SEPTIEMBRE 2025'!AY58 -> 0 | I58: ='SEPTIEMBRE 2025'!CC58 -> 0 | J58: ='SEPTIEMBRE 2025'!CD58 -> 0 | K58: ='SEPTIEMBRE 2025'!CF58 -> 0 | L58: ='SEPTIEMBRE 2025'!CG58 -> 0 | M58: ='SEPTIEMBRE 2025'!CH58 -> 0
B59: ='SEPTIEMBRE 2025'!D59 -> 0 | C59: ='SEPTIEMBRE 2025'!E59 -> 0 | D59: ='SEPTIEMBRE 2025'!H59 -> 0 | E59: ='SEPTIEMBRE 2025'!I59 -> 0 | F59: ='SEPTIEMBRE 2025'!J59 -> 0 | G59: ='SEPTIEMBRE 2025'!U59 -> 0 | H59: ='SEPTIEMBRE 2025'!AY59 -> 0 | I59: ='SEPTIEMBRE 2025'!CC59 -> 0 | J59: ='SEPTIEMBRE 2025'!CD59 -> 0 | K59: ='SEPTIEMBRE 2025'!CF59 -> 0 | L59: ='SEPTIEMBRE 2025'!CG59 -> 0 | M59: ='SEPTIEMBRE 2025'!CH59 -> 0
B60: ='SEPTIEMBRE 2025'!D60 -> 0 | C60: ='SEPTIEMBRE 2025'!E60 -> 0 | D60: ='SEPTIEMBRE 2025'!H60 -> 0 | E60: ='SEPTIEMBRE 2025'!I60 -> 0 | F60: ='SEPTIEMBRE 2025'!J60 -> 0 | G60: ='SEPTIEMBRE 2025'!U60 -> 0 | H60: ='SEPTIEMBRE 2025'!AY60 -> 0 | I60: ='SEPTIEMBRE 2025'!CC60 -> 0 | J60: ='SEPTIEMBRE 2025'!CD60 -> 0 | K60: ='SEPTIEMBRE 2025'!CF60 -> 0 | L60: ='SEPTIEMBRE 2025'!CG60 -> 0 | M60: ='SEPTIEMBRE 2025'!CH60 -> 0
B61: ='SEPTIEMBRE 2025'!D61 -> 0 | C61: ='SEPTIEMBRE 2025'!E61 -> 0 | D61: ='SEPTIEMBRE 2025'!H61 -> 0 | E61: ='SEPTIEMBRE 2025'!I61 -> 0 | F61: ='SEPTIEMBRE 2025'!J61 -> 0 | G61: ='SEPTIEMBRE 2025'!U61 -> 0 | H61: ='SEPTIEMBRE 2025'!AY61 -> 0 | I61: ='SEPTIEMBRE 2025'!CC61 -> 0 | J61: ='SEPTIEMBRE 2025'!CD61 -> 0 | K61: ='SEPTIEMBRE 2025'!CF61 -> 0 | L61: ='SEPTIEMBRE 2025'!CG61 -> 0 | M61: ='SEPTIEMBRE 2025'!CH61 -> 0
B62: ='SEPTIEMBRE 2025'!D62 -> 0 | C62: ='SEPTIEMBRE 2025'!E62 -> 0 | D62: ='SEPTIEMBRE 2025'!H62 -> 0 | E62: ='SEPTIEMBRE 2025'!I62 -> 0 | F62: ='SEPTIEMBRE 2025'!J62 -> 0 | G62: ='SEPTIEMBRE 2025'!U62 -> 0 | H62: ='SEPTIEMBRE 2025'!AY62 -> 0 | I62: ='SEPTIEMBRE 2025'!CC62 -> 0 | J62: ='SEPTIEMBRE 2025'!CD62 -> 0 | K62: ='SEPTIEMBRE 2025'!CF62 -> 0 | L62: ='SEPTIEMBRE 2025'!CG62 -> 0 | M62: ='SEPTIEMBRE 2025'!CH62 -> 0
B63: ='SEPTIEMBRE 2025'!D63 -> 0 | C63: ='SEPTIEMBRE 2025'!E63 -> 0 | D63: ='SEPTIEMBRE 2025'!H63 -> 0 | E63: ='SEPTIEMBRE 2025'!I63 -> 0 | F63: ='SEPTIEMBRE 2025'!J63 -> 0 | G63: ='SEPTIEMBRE 2025'!U63 -> 0 | H63: ='SEPTIEMBRE 2025'!AY63 -> 0 | I63: ='SEPTIEMBRE 2025'!CC63 -> 0 | J63: ='SEPTIEMBRE 2025'!CD63 -> 0 | K63: ='SEPTIEMBRE 2025'!CF63 -> 0 | L63: ='SEPTIEMBRE 2025'!CG63 -> 0 | M63: ='SEPTIEMBRE 2025'!CH63 -> 0
B64: ='SEPTIEMBRE 2025'!D64 -> 0 | C64: ='SEPTIEMBRE 2025'!E64 -> 0 | D64: ='SEPTIEMBRE 2025'!H64 -> 0 | E64: ='SEPTIEMBRE 2025'!I64 -> 0 | F64: ='SEPTIEMBRE 2025'!J64 -> 0 | G64: ='SEPTIEMBRE 2025'!U64 -> 0 | H64: ='SEPTIEMBRE 2025'!AY64 -> 0 | I64: ='SEPTIEMBRE 2025'!CC64 -> 0 | J64: ='SEPTIEMBRE 2025'!CD64 -> 0 | K64: ='SEPTIEMBRE 2025'!CF64 -> 0 | L64: ='SEPTIEMBRE 2025'!CG64 -> 0 | M64: ='SEPTIEMBRE 2025'!CH64 -> 0
...

Sheet EV
B3: INDICADOR H2 | C3: Porcentaje de mujeres con acompañamiento durante el preparto y parto
B4: Meta Nacional ≥ (O disminuir brecha) | C4: Numerador:Número de partos con acompañamiento durante el preparto y parto | D4: Denominador:Número de partos de mujeres beneficiarias | E4: Logro
C5: "REM A024 Sección A.1: Partos vaginales Sección A.2: Cesáreas" Celdas Sección A.1 C37:C38 + Sección A.2 Celdas C57:D57 | D5: "REM A024 Sección A: Información general de partos" Celda C12
B6: 0.8 | C6: =SUM(REM!D32+REM!D33+'Robson '!E18+'Robson '!F18) -> 1 | D6: =REM!D5 -> 1 | E6: =C6/D6 -> 1
B8: INDICADOR H3 | C8: Porcentaje de recién nacidos y nacidas con peso ≥ a 2.500 grs con contacto piel a piel ≥ a 30 min supervisado por equipo
B9: Meta Nacional ≥ (O disminuir brecha) | C9: Numerador:Número de recién nacidos con peso ≥ a 2.500 grs con contacto piel a piel ≥ a 30 min | D9: Denominador: Número de nacidos y nacidas con peso ≥ a 2.500 grs | E9: Logro | G9: ACTUAL
C10: REM A24 Sección A: Información general de partos (Celdas U13:U16) | D10: REM A24 Sección D1: Información general de RN vivos (Celdas I109:K109)
B11: 0.8 | C11: =SUM(REM!V5) -> 0 | D11: 159 | E11: =IFERROR(C11/D11,"-") -> 0 | G11: PROPUESTA ACTUAL
B13: 0.8 | C13: =SUM(REM!V5+REM!X5) -> 2 | D13: 159 | E13: =IFERROR(C13/D13,"-") -> 0.012578616 | G13: SUGERENCIA

Sheet Robson 
C4: SECCION A.2: CESÁREAS (responsabilidad del Médico Jefe del Servicio de Obstetricia)
C5: CLASIFICACIÓN SEGÚN MODELO DE ROBSON | E5: PROGRAMADA | F5: URGENCIA
C6: GRUPO 1: Nulíparas, embarazo único, cefálica, ≥37 semanas en trabajo de parto espontáneo | E6: =COUNTIFS('SEPTIEMBRE 2025'!BA:BA, "Grupo 1",'SEPTIEMBRE 2025'!AY:AY, "ces.electiva") -> 0 | F6: =COUNTIFS('SEPTIEMBRE 2025'!BA:BA, "Grupo 1",'SEPTIEMBRE 2025'!AY:AY, "ces. urgencia") -> 0 | H6: Total Robson Clasificadas | J6: =SUM(J7:J8) -> 2
C7: GRUPO 2: Nulíparas, Embarazo único, cefálica, ≥37 semanas, cesárea programada o con inducción de trabajo de parto. | D7: Total cesáreas grupo 2 | E7: =SUM(H11:H12) -> 0 | F7: =SUM(I11:I12) -> 1 | H7: electivas | J7: =SUM(E6:E17) -> 1
D8: Por requerimiento materno | E8: 0 | F8: 0 | H8: urgencia | J8: =SUM(F6:F17) -> 1
C9: GRUPO 3: Multípara, sin cesárea previa, embarazo único, cefálica, ≥37 semanas en trabajo de parto espontáneo | E9: =COUNTIFS('SEPTIEMBRE 2025'!AY:AY, "CES.ELECTIVA",'SEPTIEMBRE 2025'!BA:BA, "Grupo 3") -> 1 | F9: =COUNTIFS('SEPTIEMBRE 2025'!AY:AY, "CES. URGENCIA",'SEPTIEMBRE 2025'!BA:BA, "Grupo 3") -> 0
C10: GRUPO 4: Multípara, sin cesárea previa, embarazo único, cefálica, ≥37 semanas, cesárea programada o con inducción de trabajo de parto. | E10: =SUM(H14:H15) -> 0 | F10: =SUM(I14:I15) -> 0 | H10: R2.a + R2.b Electivo+ | I10: R2.a + R2.b Urgencia
C11: GRUPO 5: Multíparas con al menos 1 cesárea previa, embarazo unico, cefálica, ≥37 semanas. | D11: 5.1: con 1 cesárea previa | E11: =COUNTIFS('SEPTIEMBRE 2025'!AY:AY, "CES.ELECTIVA",'SEPTIEMBRE 2025'!BA:BA, "Grupo 5.1") -> 0 | F11: =COUNTIFS('SEPTIEMBRE 2025'!AY:AY, "CES. URGENCIA",'SEPTIEMBRE 2025'!BA:BA, "Grupo 5.1") -> 0 | H11: =COUNTIFS('SEPTIEMBRE 2025'!AY:AY, "CES.ELECTIVA",'SEPTIEMBRE 2025'!BA:BA, "Grupo 2.A") -> 0 | I11: =COUNTIFS('SEPTIEMBRE 2025'!AY:AY, "CES. URGENCIA",'SEPTIEMBRE 2025'!BA:BA, "Grupo 2.A") -> 0
D12: 5.2: 2 o más cesareas previas | E12: =COUNTIFS('SEPTIEMBRE 2025'!AY:AY, "CES.ELECTIVA",'SEPTIEMBRE 2025'!BA:BA, "Grupo 5.2") -> 0 | F12: =COUNTIFS('SEPTIEMBRE 2025'!AY:AY, "CES. URGENCIA",'SEPTIEMBRE 2025'!BA:BA, "Grupo 5.2") -> 0 | H12: =COUNTIFS('SEPTIEMBRE 2025'!AY:AY, "CES.ELECTIVA",'SEPTIEMBRE 2025'!BA:BA, "Grupo 2.B") -> 0 | I12: =COUNTIFS('SEPTIEMBRE 2025'!AY:AY, "CES. URGENCIA",'SEPTIEMBRE 2025'!BA:BA, "Grupo 2.B") -> 1
C13: GRUPO 6: Nulíparas, embarazo único, podálica | E13: =COUNTIFS('SEPTIEMBRE 2025'!BA:BA, "Grupo 6",'SEPTIEMBRE 2025'!AY:AY, "ces.electiva") -> 0 | F13: =COUNTIFS('SEPTIEMBRE 2025'!BA:BA, "Grupo 6",'SEPTIEMBRE 2025'!AY:AY, "ces. urgencia") -> 0 | H13: R4.a + R4.b Electivo+ | I13: R4.a + R4.b Urgencia
C14: GRUPO 7: Multíparas, embarazo único, podálica, con 1 o más cesáreas previas. | E14: =COUNTIFS('SEPTIEMBRE 2025'!BA:BA, "Grupo 7",'SEPTIEMBRE 2025'!AY:AY, "ces.electiva") -> 0 | F14: =COUNTIFS('SEPTIEMBRE 2025'!BA:BA, "Grupo 7",'SEPTIEMBRE 2025'!AY:AY, "ces. urgencia") -> 0 | H14: =COUNTIFS('SEPTIEMBRE 2025'!AY:AY, "CES.ELECTIVA",'SEPTIEMBRE 2025'!BA:BA, "Grupo 4.A") -> 0 | I14: =COUNTIFS('SEPTIEMBRE 2025'!AY:AY, "CES. URGENCIA",'SEPTIEMBRE 2025'!BA:BA, "Grupo 4.A") -> 0
C15: GRUPO 8: Todas las mujeres con embarazo múltiple, incluidas las que tienen 1 o más cesáreas previas. | E15: =COUNTIFS('SEPTIEMBRE 2025'!BA:BA, "Grupo 8",'SEPTIEMBRE 2025'!AY:AY, "ces.electiva") -> 0 | F15: =COUNTIFS('SEPTIEMBRE 2025'!BA:BA, "Grupo 8",'SEPTIEMBRE 2025'!AY:AY, "ces. urgencia") -> 0 | H15: =COUNTIFS('SEPTIEMBRE 2025'!AY:AY, "CES.ELECTIVA",'SEPTIEMBRE 2025'!BA:BA, "Grupo 4.B") -> 0 | I15: =COUNTIFS('SEPTIEMBRE 2025'!AY:AY, "CES. URGENCIA",'SEPTIEMBRE 2025'!BA:BA, "Grupo 4.B") -> 0
